Workbook

Sheet April
A1: Bodkin Way | B1: 1 | C1: 2 | D1: 3 | E1: 4 | F1: 5 | G1: 6 | H1: 7 | I1: 8 | J1: 9 | K1: 10 | L1: 11 | M1: 12 | N1: 13 | O1: 14 | P1: 15 | Q1: 16 | R1: 17 | S1: 18 | T1: 19 | U1: 20 | V1: 21 | W1: 22 | X1: 23 | Y1: 24 | Z1: 25 | AA1: 26 | AB1: 27 | AC1: 28 | AD1: 29 | AE1: 30 | AF1: ASI | AG1: Over/Under
A2: April | B2: W | C2: TH | D2: F | E2: S | F2: SU | G2: M | H2: T | I2: W | J2: TH | K2: F | L2: S | M2: SU | N2: M | O2: T | P2: W | Q2: T | R2: F | S2: S | T2: SU | U2: M | V2: T | W2: W | X2: TH | Y2: F | Z2: S | AA2: SU | AB2: M | AC2: T | AD2: W | AE2: TH | AF2: =SUM(AF5,AF8,AF11,AF14,AF17,AF20,AF23,AF26,AF29,AF32,AF35,AF38,AF41,AF44,AF47,AF50,AF53,AF56,AF59,AF62,AF65) -> 61 | AG2: Hours
A3: Ellen | B3: A | C3: A | D3: A | G3: A | H3: A | I3: A | J3: A | K3: A | N3: A | O3: A | P3: A | Q3: A | R3: A | U3: A | V3: A | W3: A | X3: A | Y3: A | AB3: A | AC3: A | AD3: A | AE3: A | AF3: =SUM(B3:AE3) -> 0
A4: Middleton | B4: 7.5 | C4: 7.5 | D4: 7.5 | G4: 7.5 | H4: 7.5 | I4: 7.5 | J4: 7.5 | K4: 7.5 | N4: 7.5 | O4: 7.5 | P4: 7.5 | Q4: 7.5 | R4: 7.5 | U4: 7.5 | V4: 7.5 | W4: 7.5 | X4: 7.5 | Y4: 7.5 | AB4: 7.5 | AC4: 7.5 | AD4: 7.5 | AE4: 7.5 | AF4: =SUM(B4:AE4) -> 165
A5: RM | AF5: =SUM(B5:AE5) -> 0
A6: Charlotte | B6: D | C6: A | G6: D | H6: A | K6: DS | M6: DS | N6: A | O6: A | S6: DS | U6: A | Y6: D | AB6: A | AE6: DS | AF6: =SUM(B6:AE6) -> 0
A7: Watson | B7: 15 | C7: 3 | G7: 15 | H7: 8 | J7: 5 | K7: 15 | L7: 0.5 | M7: 15 | N7: 8 | O7: 7.5 | S7: 15 | T7: 0.5 | U7: 7.5 | X7: 4.5 | Y7: 15 | AB7: 7.5 | AE7: 15 | AF7: =SUM(B7:AE7) -> 157 | AG7: =SUM(AF7-AF67) -> -3
A8: DM | AF8: {=SUMPRODUCT(--(RIGHT(B6:AE6,1)="S"))} -> 4
A9: Philip | E9: DS | F9: DS | K9: DS | L9: DS | Q9: DS | R9: DS | W9: DS | X9: DS | AC9: DS | AD9: DS | AF9: =SUM(B9:AE9) -> 0
A10: Thomas | E10: 15 | F10: 15 | G10: 0.5 | J10: 5 | K10: 15 | L10: 15 | M10: 0.5 | Q10: 15 | R10: 15 | S10: 0.5 | W10: 15 | X10: 15 | Y10: 0.5 | AC10: 15 | AD10: 15 | AE10: 0.5 | AF10: =SUM(B10:AE10) -> 157.5 | AG10: =SUM(AF10-AF67) -> -2.5
A11: SRSW | AF11: {=SUMPRODUCT(--(RIGHT(B9:AE9,1)="S"))} -> 10
AF12: =SUM(B12:AE12) -> 0
AF13: =SUM(B13:AE13) -> 0 | AG13: =SUM(AF13-AF67) -> -160
AF14: =SUM(B14:AE14) -> 0
A15: Michelle | C15: DS | D15: DS | I15: DS | J15: DS | O15: DS | P15: DS | U15: DS | V15: DS | AA15: DS | AB15: DS | AF15: =SUM(B15:AE15) -> 0
A16: McSporran | C16: 15 | D16: 15 | E16: 0.5 | I16: 15 | J16: 15 | K16: 0.5 | O16: 15 | P16: 15 | Q16: 0.5 | U16: 15 | V16: 15 | W16: 0.5 | X16: 4.5 | AA16: 15 | AB16: 15 | AC16: 0.5 | AF16: =SUM(B16:AE16) -> 157 | AG16: =SUM(AF16-AF67) -> -3
A17: SRSW | AF17: {=SUMPRODUCT(--(RIGHT(B15:AE15,1)="S"))} -> 10
A18: Jack | B18: DS | C18: DS | H18: DS | I18: DS | N18: DS | O18: DS | T18: DS | U18: DS | Z18: DS | AA18: DS | AF18: =SUM(B18:AE18) -> 0
A19: McMahon | B19: 15 | C19: 15 | D19: 0.5 | H19: 15 | I19: 15 | J19: 4.5 | N19: 15 | O19: 15 | P19: 0.5 | T19: 15 | U19: 15 | V19: 0.5 | X19: 4.5 | Z19: 15 | AA19: 15 | AB19: 0.5 | AF19: =SUM(B19:AE19) -> 161 | AG19: =SUM(AF19-AF67) -> 1
A20: Q. RSW | AF20: {=SUMPRODUCT(--(RIGHT(B18:AE18,1)="S"))} -> 10
A21: Sarah | F21: DS | G21: DS | L21: DS | M21: DS | P21: DS | R21: DS | S21: DS | X21: DS | Y21: DS | AD21: DS | AF21: =SUM(B21:AE21) -> 0
A22: Newson | F22: 15 | G22: 15 | H22: 0.5 | J22: 4 | L22: 15 | M22: 15 | N22: 0.5 | P22: 15 | Q22: 0.5 | R22: 15 | S22: 15 | T22: 0.5 | X22: 15 | Y22: 15 | Z22: 0.5 | AD22: 15 | AE22: 0.5 | AF22: =SUM(B22:AE22) -> 157 | AG22: =SUM(AF22-AF67) -> -3
A23: Q. RSW | AF23: {=SUMPRODUCT(--(RIGHT(B21:AE21,1)="S"))} -> 10
AF24: =SUM(B24:AE24) -> 0
AF25: =SUM(B25:AE25) -> 0 | AG25: =SUM(AF25-AF67) -> -160
AF26: =SUM(B26:AE26) -> 0
A27: Sam | D27: DS | E27: DS | I27: * | J27: DS | K27: 2 | P27: 2 | Q27: DS | V27: DS | W27: DS | AB27: DS | AC27: DS | AF27: =SUM(B27:AE27) -> 4
A28: Lawrence | D28: 15 | E28: 15 | F28: 0.5 | J28: 15 | K28: 15.5 | P28: 15 | Q28: 15 | R28: 0.5 | V28: 15 | W28: 15 | X28: 4.5 | AB28: 15 | AC28: 15 | AD28: 0.5 | AF28: =SUM(B28:AE28) -> 156.5 | AG28: =SUM(AF28-AF67) -> -3.5
A29: UQ. RSW | AF29: {=SUMPRODUCT(--(RIGHT(B27:AE27,1)="S"))} -> 8
A30: Olivia | B30: DS | G30: DS | H30: DS | N30: DS | O30: D | S30: DS | T30: DS | Y30: DS | Z30: DS | AE30: DS | AF30: =SUM(B30:AE30) -> 0
A31: Machnik | B31: 15 | C31: 0.5 | G31: 15 | H31: 15 | I31: 0.5 | J31: 4 | L31: * | M31: * | N31: 15 | O31: 15 | S31: 15 | T31: 15 | U31: 0.5 | X31: 4.5 | Y31: 15 | Z31: 15 | AA31: 0.5 | AE31: 11 | AF31: =SUM(B31:AE31) -> 156.5 | AG31: =SUM(AF31-AF67) -> -3.5
A32: UQ. RSW | AF32: {=SUMPRODUCT(--(RIGHT(B30:AE30,1)="S"))} -> 9
A33: James | AF33: =SUM(B33:AE33) -> 0
A34: Logan | AF34: =SUM(B34:AE34) -> 0
A35: Bank | AF35: {=SUMPRODUCT(--(RIGHT(B33:AE33,1)="S"))} -> 0
AF36: =SUM(B36:AE36) -> 0
AF37: =SUM(B37:AE37) -> 0
AF38: {=SUMPRODUCT(--(RIGHT(B36:AE36,1)="S"))} -> 0
AF39: =SUM(B39:AE39) -> 0
AF40: =SUM(B40:AE40) -> 0
...

Sheet May
A1: Bodkin Way | B1: 1 | C1: 2 | D1: 3 | E1: 4 | F1: 5 | G1: 6 | H1: 7 | I1: 8 | J1: 9 | K1: 10 | L1: 11 | M1: 12 | N1: 13 | O1: 14 | P1: 15 | Q1: 16 | R1: 17 | S1: 18 | T1: 19 | U1: 20 | V1: 21 | W1: 22 | X1: 23 | Y1: 24 | Z1: 25 | AA1: 26 | AB1: 27 | AC1: 28 | AD1: 29 | AE1: 30 | AF1: 31 | AG1: ASI | AH1: Over/Under
A2: May | B2: F | C2: S | D2: SU | E2: M | F2: T | G2: W | H2: TH | I2: F | J2: S | K2: SU | L2: M | M2: T | N2: W | O2: TH | P2: F | Q2: S | R2: SU | S2: M | T2: T | U2: W | V2: TH | W2: F | X2: S | Y2: SU | Z2: M | AA2: T | AB2: W | AC2: TH | AD2: F | AE2: S | AF2: SU | AG2: =SUM(AG5,AG8,AG11,AG14,AG17,AG20,AG23,AG26,AG29,AG32,AG35,AG38,AG41,AG44,AG47,AG50,AG53,AG56) -> 58 | AH2: Hours
A3: Ellen | B3: A | E3: A | F3: A | G3: A | H3: A | I3: A | L3: A | M3: A | N3: A | O3: A | P3: A | S3: A | T3: A | U3: A | V3: A | W3: A | Z3: A | AA3: A | AB3: A | AC3: A | AD3: 1 | AG3: =SUM(B3:AF3) -> 1
A4: Middleton | B4: 7.5 | E4: 7.5 | F4: 7.5 | G4: 7.5 | H4: 7.5 | I4: 7.5 | L4: 7.5 | M4: 7.5 | N4: 7.5 | O4: 7.5 | P4: 7.5 | S4: 7.5 | T4: 7.5 | U4: 7.5 | V4: 7.5 | W4: 7.5 | Z4: 7.5 | AA4: 7.5 | AB4: 7.5 | AC4: 7.5 | AD4: 7.5 | AG4: =SUM(B4:AF4) -> 157.5
A5: RM | AG5: =SUM(B5:AF5) -> 0
A6: Charlotte | B6: A | E6: A | F6: A | G6: A | H6: A | I6: A | L6: A | M6: A | N6: A | O6: A | P6: A | S6: A | T6: A | U6: A | V6: A | W6: A | Z6: A | AA6: A | AB6: A | AC6: A | AD6: A | AG6: =SUM(B6:AF6) -> 0
A7: Watson | B7: 7.5 | E7: 7.5 | F7: 7.5 | G7: 7.5 | H7: 7.5 | I7: 7.5 | L7: 7.5 | M7: 7.5 | N7: 7.5 | O7: 7.5 | P7: 7.5 | S7: 7.5 | T7: 7.5 | U7: 7.5 | V7: 7.5 | W7: 7.5 | Z7: 7.5 | AA7: 7.5 | AB7: 7.5 | AC7: 7.5 | AD7: 7.5 | AG7: =SUM(B7:AF7) -> 157.5 | AH7: =SUM(AG7-AG58) -> -8
A8: DM | AG8: =SUM(B8:AF8) -> 0
A9: Philip | E9: DS | F9: DS | K9: DS | L9: DS | Q9: 2 | R9: 2 | W9: DS | X9: DS | AC9: DS | AD9: DS | AG9: =SUM(B9:AF9) -> 4
A10: Thomas | E10: 15 | F10: 15 | G10: 0.5 | H10: 5 | K10: 15 | L10: 15 | M10: 0.5 | Q10: 15 | R10: 15 | W10: 15 | X10: 15 | Y10: 0.5 | AC10: 15 | AD10: 15 | AE10: 0.5 | AG10: =SUM(B10:AF10) -> 157 | AH10: =SUM(AG10-AG58) -> -8.5
A11: SRSW | E11: 1 | F11: 1 | K11: 1 | L11: 1 | W11: 1 | X11: 1 | AC11: 1 | AD11: 1 | AG11: =SUM(B11:AF11) -> 8
AG12: =SUM(B12:AF12) -> 0
AG13: =SUM(B13:AF13) -> 0 | AH13: =SUM(AG13-AG58) -> -165.5
AG14: =SUM(B14:AF14) -> 0
A15: Michelle | C15: DS | D15: DS | I15: DS | J15: DS | O15: DS | P15: DS | U15: DS | V15: DS | AA15: DS | AB15: DS | AG15: =SUM(B15:AF15) -> 0
A16: McSporran | C16: 15 | D16: 15 | E16: 0.5 | H16: 5 | I16: 15 | J16: 15 | K16: 0.5 | O16: 15 | P16: 15 | Q16: 0.5 | U16: 15 | V16: 15 | W16: 0.5 | AA16: 15 | AB16: 15 | AC16: 0.5 | AG16: =SUM(B16:AF16) -> 157.5 | AH16: =SUM(AG16-AG58) -> -8
A17: SRSW | C17: 1 | D17: 1 | I17: 1 | J17: 1 | O17: 1 | P17: 1 | U17: 1 | V17: 1 | AA17: 1 | AB17: 1 | AG17: =SUM(B17:AF17) -> 10
A18: Jack | B18: DS | G18: DS | H18: DS | M18: DS | N18: DS | S18: DS | T18: DS | Y18: DS | Z18: DS | AE18: 2 | AF18: 2 | AG18: =SUM(B18:AF18) -> 4
A19: McMahon | B19: 15 | C19: 0.5 | G19: 15 | H19: 15 | I19: 0.5 | M19: 15 | N19: 15 | O19: 0.5 | S19: 15 | T19: 15 | U19: 0.5 | V19: 5 | Y19: 15 | Z19: 15 | AA19: 0.5 | AE19: 15 | AF19: 15 | AG19: =SUM(B19:AF19) -> 172.5 | AH19: =SUM(AG19-AG58) -> 7
A20: Q. RSW | B20: 1 | G20: 1 | H20: 1 | M20: 1 | N20: 1 | S20: 1 | T20: 1 | Y20: 1 | Z20: 1 | AG20: =SUM(B20:AF20) -> 9
A21: Sarah | F21: DS | G21: DS | L21: DS | M21: DS | R21: DS | S21: DS | X21: DS | Y21: DS | AD21: DS | AE21: DS | AG21: =SUM(B21:AF21) -> 0
A22: Newson | F22: 15 | G22: 15 | H22: 5.5 | L22: 15 | M22: 15 | N22: 0.5 | R22: 15 | S22: 15 | T22: 0.5 | V22: 4 | X22: 15 | Y22: 15 | Z22: 0.5 | AD22: 15 | AE22: 15 | AF22: 0.5 | AG22: =SUM(B22:AF22) -> 161.5 | AH22: =SUM(AG22-AG58) -> -4
A23: Q. RSW | F23: 1 | G23: 1 | L23: 1 | M23: 1 | R23: 1 | S23: 1 | X23: 1 | Y23: 1 | AD23: 1 | AE23: 1 | AG23: =SUM(B23:AF23) -> 10
AG24: =SUM(B24:AF24) -> 0
AG25: =SUM(B25:AF25) -> 0 | AH25: =SUM(AG25-AG58) -> -165.5
AG26: =SUM(B26:AF26) -> 0
A27: Sam | B27: DS | D27: DS | E27: DS | J27: DS | K27: DS | P27: DS | Q27: DS | V27: DS | W27: DS | AB27: DS | AC27: DS | AG27: =SUM(B27:AF27) -> 0
A28: Lawrence | B28: 15 | C28: 0.5 | D28: 15 | E28: 15 | F28: 0.5 | H28: 4 | I28: * | J28: 15 | K28: 15 | L28: 0.5 | P28: 15 | Q28: 15 | R28: 0.5 | V28: 15 | W28: 15 | X28: 0.5 | AB28: 15 | AC28: 15 | AD28: 0.5 | AG28: =SUM(B28:AF28) -> 172 | AH28: =SUM(AG28-AG58) -> 6.5
A29: UQ. RSW | B29: 1 | D29: 1 | E29: 1 | J29: 1 | K29: 1 | P29: 1 | Q29: 1 | V29: 1 | W29: 1 | AB29: 1 | AC29: 1 | AG29: =SUM(B29:AF29) -> 11
A30: Olivia | C30: DS | H30: DS | I30: DS | N30: DS | O30: DS | T30: DS | U30: DS | Z30: DS | AA30: DS | AF30: DS | AG30: =SUM(B30:AF30) -> 0
A31: Machnik | C31: 15 | D31: 0.5 | H31: 15 | I31: 15 | J31: 0.5 | N31: 15 | O31: 15 | P31: 0.5 | T31: 15 | U31: 15 | V31: 4.5 | Z31: 15 | AA31: 15 | AB31: 0.5 | AF31: 15 | AG31: =SUM(B31:AF31) -> 156.5 | AH31: =SUM(AG31-AG58) -> -9
A32: UQ. RSW | C32: 1 | H32: 1 | I32: 1 | N32: 1 | O32: 1 | T32: 1 | U32: 1 | Z32: 1 | AA32: 1 | AF32: 1 | AG32: =SUM(B32:AF32) -> 10
A33: James | AG33: 0
A34: Logan | AG34: =SUM(B34:AF34) -> 0
A35: Bank | AG35: =SUM(B35:AF35) -> 0
AG36: 0
AG37: =SUM(B37:AF37) -> 0
AG38: =SUM(B38:AF38) -> 0
AG39: 0
AG40: =SUM(B40:AF40) -> 0
...

Sheet June
A1: Bodkin Way | B1: 1 | C1: 2 | D1: 3 | E1: 4 | F1: 5 | G1: 6 | H1: 7 | I1: 8 | J1: 9 | K1: 10 | L1: 11 | M1: 12 | N1: 13 | O1: 14 | P1: 15 | Q1: 16 | R1: 17 | S1: 18 | T1: 19 | U1: 20 | V1: 21 | W1: 22 | X1: 23 | Y1: 24 | Z1: 25 | AA1: 26 | AB1: 27 | AC1: 28 | AD1: 29 | AE1: 30 | AF1: ASI | AG1: Over/Under
A2: June | B2: M | C2: T | D2: W | E2: TH | F2: F | G2: S | H2: SU | I2: M | J2: T | K2: W | L2: TH | M2: F | N2: S | O2: SU | P2: M | Q2: T | R2: W | S2: TH | T2: F | U2: S | V2: SU | W2: M | X2: T | Y2: W | Z2: TH | AA2: F | AB2: S | AC2: SU | AD2: M | AE2: T | AF2: =SUM(AF5,AF8,AF11,AF17,AF20,AF23,AF26,AF29,AF32,AF35,AF38,AF41,AF44,AF47,AF50,AF53,AF56,AF59,AF62,AF65) -> 59 | AG2: Hours
A3: Ellen | B3: A | C3: A | D3: A | E3: A | F3: A | I3: A | J3: A | K3: A | L3: A | M3: A | P3: A | Q3: A | R3: A | S3: A | T3: A | W3: A | X3: A | Y3: A | Z3: A | AA3: A | AD3: A | AE3: A | AF3: =SUM(B3:AE3) -> 0
A4: Middleton | B4: 7.5 | C4: 7.5 | D4: 7.5 | E4: 7.5 | F4: 7.5 | I4: 7.5 | J4: 7.5 | K4: 7.5 | L4: 7.5 | M4: 7.5 | P4: 7.5 | Q4: 7.5 | R4: 7.5 | S4: 7.5 | T4: 7.5 | W4: 7.5 | X4: 7.5 | Y4: 7.5 | Z4: 7.5 | AA4: 7.5 | AD4: 7.5 | AE4: 7.5 | AF4: =SUM(B4:AE4) -> 165
A5: RM | AF5: =SUM(B5:AE5) -> 0
A6: Charlotte | B6: A | C6: A | F6: DS | G6: DS | K6: A | L6: A | M6: A | P6: A | Q6: A | R6: A | S6: A | T6: A | W6: A | X6: A | Y6: A | Z6: A | AA6: A | AD6: A | AE6: A | AF6: =SUM(B6:AE6) -> 0
A7: Watson | B7: 7.5 | C7: 7.5 | F7: 15 | G7: 15 | K7: 7.5 | L7: 7.5 | M7: 7.5 | P7: 7.5 | Q7: 7.5 | R7: 7.5 | S7: 7.5 | T7: 7.5 | W7: 7.5 | X7: 7.5 | Y7: 7.5 | Z7: 7.5 | AA7: 7.5 | AD7: 7.5 | AE7: 7.5 | AF7: =SUM(B7:AE7) -> 157.5 | AG7: =SUM(AF7-AF67) -> -2.5
A8: DM | F8: 1 | G8: 1 | AF8: =SUM(B8:AE8) -> 2
A9: Philip | D9: DS | E9: DS | J9: DS | K9: DS | P9: DS | Q9: DS | V9: DS | W9: DS | AB9: DS | AC9: DS | AF9: =SUM(B9:AE9) -> 0
A10: Thomas | D10: 15 | E10: 15 | F10: 0.5 | J10: 15 | K10: 15 | L10: 5.5 | P10: 15 | Q10: 15 | R10: 0.5 | V10: 15 | W10: 15 | X10: 0.5 | Z10: 5 | AB10: 15 | AC10: 15 | AD10: 0.5 | AF10: =SUM(B10:AE10) -> 162.5 | AG10: =SUM(AF10-AF67) -> 2.5
A11: SRSW | D11: 1 | E11: 1 | J11: 1 | K11: 1 | P11: 1 | Q11: 1 | V11: 1 | W11: 1 | AB11: 1 | AC11: 1 | AF11: =SUM(B11:AE11) -> 10
AF12: =SUM(B12:AE12) -> 0
AF13: =SUM(B13:AE13) -> 0 | AG13: =SUM(AF13-AF67) -> -160
AF14: =SUM(B14:AE14) -> 0
A15: Michelle | B15: DS | C15: DS | H15: DS | I15: DS | N15: DS | O15: DS | T15: DS | U15: DS | Z15: DS | AA15: DS | AF15: =SUM(B15:AE15) -> 0
A16: McSporran | B16: 15 | C16: 15 | D16: 0.5 | H16: 15 | I16: 15 | J16: 0.5 | L16: 5 | N16: 15 | O16: 15 | P16: 0.5 | T16: 15 | U16: 15 | V16: 0.5 | Z16: 15 | AA16: 15 | AB16: 0.5 | AF16: =SUM(B16:AE16) -> 157.5 | AG16: =SUM(AF16-AF67) -> -2.5
A17: SRSW | B17: 1 | C17: 1 | H17: 1 | I17: 1 | N17: 1 | O17: 1 | T17: 1 | U17: 1 | Z17: 1 | AA17: 1 | AF17: =SUM(B17:AE17) -> 10
A18: Jack | L18: DS | M18: DS | R18: DS | S18: DS | X18: DS | Y18: DS | AD18: DS | AE18: DS | AF18: =SUM(B18:AE18) -> 0
A19: McMahon | F19: 15 | G19: 15 | L19: 15 | M19: 15 | N19: 0.5 | R19: 15 | S19: 15 | T19: 0.5 | X19: 15 | Y19: 15 | Z19: 5.5 | AD19: 15 | AE19: 15 | AF19: =SUM(B19:AE19) -> 156.5 | AG19: =SUM(AF19-AF67) -> -3.5
A20: Q. RSW | L20: 1 | M20: 1 | R20: 1 | S20: 1 | X20: 1 | Y20: 1 | AD20: 1 | AE20: 1 | AF20: =SUM(B20:AE20) -> 8
A21: Sarah | E21: DS | F21: DS | K21: DS | L21: DS | Q21: DS | R21: DS | W21: DS | X21: DS | AC21: 2 | AD21: 2 | AF21: =SUM(B21:AE21) -> 4
A22: Newson | E22: 15 | F22: 15 | G22: 0.5 | K22: 15 | L22: 15 | M22: 0.5 | Q22: 15 | R22: 15 | S22: 0.5 | W22: 15 | X22: 15 | Y22: 0.5 | AC22: 15 | AD22: 15 | AF22: =SUM(B22:AE22) -> 152 | AG22: =SUM(AF22-AF67) -> -8
A23: Q. RSW | E23: 1 | F23: 1 | K23: 1 | L23: 1 | Q23: 1 | R23: 1 | W23: 1 | X23: 1 | AF23: =SUM(B23:AE23) -> 8
AF24: =SUM(B24:AE24) -> 0
AF25: =SUM(B25:AE25) -> 0 | AG25: =SUM(AF25-AF67) -> -160
AF26: =SUM(B26:AE26) -> 0
A27: Sam | C27: DS | D27: DS | I27: DS | J27: DS | O27: DS | P27: DS | T27: * | U27: DS | V27: DS | AA27: DS | AB27: DS | AF27: =SUM(B27:AE27) -> 0
A28: Lawrence | C28: 15 | D28: 15 | E28: 0.5 | I28: 15 | J28: 15 | K28: 0.5 | L28: 4 | O28: 15 | P28: 15 | Q28: 0.5 | U28: 15 | V28: 15 | W28: 0.5 | Z28: 4 | AA28: 15 | AB28: 15 | AC28: 0.5 | AF28: =SUM(B28:AE28) -> 160.5 | AG28: =SUM(AF28-AF67) -> 0.5
A29: UQ. RSW | C29: 1 | D29: 1 | I29: 1 | J29: 1 | O29: 1 | P29: 1 | U29: 1 | V29: 1 | AA29: 1 | AB29: 1 | AF29: =SUM(B29:AE29) -> 10
A30: Olivia | B30: DS | G30: DS | H30: DS | M30: DS | N30: DS | S30: DS | T30: DS | Y30: DS | Z30: DS | AC30: DS | AE30: DS | AF30: =SUM(B30:AE30) -> 0
A31: Machnik | B31: 15 | C31: 0.5 | G31: 15 | H31: 15 | I31: 0.5 | L31: 4 | M31: 15 | N31: 15 | O31: 0.5 | S31: 15 | T31: DS | U31: 0.5 | Y31: 15 | Z31: 15 | AA31: 0.5 | AC31: 15 | AE31: 15 | AF31: =SUM(B31:AE31) -> 156.5 | AG31: =SUM(AF31-AF67) -> -3.5
A32: UQ. RSW | B32: 1 | G32: 1 | H32: 1 | M32: 1 | N32: 1 | S32: 1 | T32: 1 | Y32: 1 | Z32: 1 | AC32: 1 | AE32: 1 | AF32: =SUM(B32:AE32) -> 11
A33: James | AF33: =SUM(B33:AE33) -> 0
A34: Logan | AF34: =SUM(B34:AE34) -> 0
A35: Bank | AF35: =SUM(B35:AE35) -> 0
AF36: =SUM(B36:AE36) -> 0
AF37: =SUM(B37:AE37) -> 0
AF38: =SUM(B38:AE38) -> 0
AF39: =SUM(B39:AE39) -> 0
AF40: =SUM(B40:AE40) -> 0
...

Sheet July
A1: Bodkin Way | B1: 1 | C1: 2 | D1: 3 | E1: 4 | F1: 5 | G1: 6 | H1: 7 | I1: 8 | J1: 9 | K1: 10 | L1: 11 | M1: 12 | N1: 13 | O1: 14 | P1: 15 | Q1: 16 | R1: 17 | S1: 18 | T1: 19 | U1: 20 | V1: 21 | W1: 22 | X1: 23 | Y1: 24 | Z1: 25 | AA1: 26 | AB1: 27 | AC1: 28 | AD1: 29 | AE1: 30 | AF1: 31 | AG1: ASI | AH1: Over/Under
A2: July | B2: W | C2: TH | D2: F | E2: S | F2: SU | G2: M | H2: T | I2: W | J2: TH | K2: F | L2: S | M2: SU | N2: M | O2: T | P2: W | Q2: TH | R2: F | S2: S | T2: SU | U2: M | V2: T | W2: W | X2: TH | Y2: F | Z2: S | AA2: SU | AB2: M | AC2: T | AD2: W | AE2: TH | AF2: F | AG2: =SUM(AG5,AG8,AG11,AG17,AG20,AG23,AG26,AG29,AG32,AG35,AG38,AG41,AG44,AG47,AG50,AG53,AG56, AG59) -> 57 | AH2: Hours
A3: Ellen | B3: A | C3: A | D3: A | G3: A | H3: A | I3: A | J3: A | K3: A | N3: A | O3: A | P3: A | Q3: A | R3: A | U3: A | V3: A | W3: A | X3: A | Y3: A | AB3: A | AC3: A | AD3: A | AE3: A | AF3: A | AG3: =SUM(B3:AF3) -> 0
A4: Middleton | B4: 7.5 | C4: 7.5 | D4: 7.5 | G4: 7.5 | H4: 7.5 | I4: 7.5 | J4: 7.5 | K4: 7.5 | N4: 7.5 | O4: 7.5 | P4: 7.5 | Q4: 7.5 | R4: 7.5 | U4: 7.5 | V4: 7.5 | W4: 7.5 | X4: 7.5 | Y4: 7.5 | AB4: 7.5 | AC4: 7.5 | AD4: 7.5 | AE4: 7.5 | AF4: 7.5 | AG4: =SUM(B4:AF4) -> 172.5
A5: RM | AG5: =SUM(B5:AF5) -> 0
A6: Charlotte | B6: A | C6: A | D6: A | G6: A | H6: A | I6: A | J6: A | K6: A | N6: A | O6: A | P6: A | Q6: A | R6: A | U6: A | V6: A | W6: A | X6: A | Y6: A | AB6: A | AC6: A | AD6: A | AE6: A | AF6: A | AG6: =SUM(B6:AF6) -> 0
A7: Watson | B7: 7.5 | C7: 7.5 | D7: 7.5 | G7: 7.5 | H7: 7.5 | I7: 7.5 | J7: 7.5 | K7: 7.5 | N7: 7.5 | O7: 7.5 | P7: 7.5 | Q7: 7.5 | R7: 7.5 | U7: 7.5 | V7: 7.5 | W7: 7.5 | X7: 7.5 | Y7: 7.5 | AB7: 7.5 | AC7: 7.5 | AD7: 7.5 | AE7: 7.5 | AF7: 7.5 | AG7: =SUM(B7:AF7) -> 172.5 | AH7: =SUM(AG7-AG61) -> 7
A8: DM | AG8: =SUM(B8:AF8) -> 0
A9: Philip | D9: DS | E9: DS | J9: DS | K9: DS | P9: DS | Q9: DS | V9: DS | W9: DS | AB9: DS | AC9: DS | AG9: =SUM(B9:AF9) -> 0
A10: Thomas | D10: 15 | E10: 15 | F10: 0.5 | J10: 15 | K10: 15 | L10: 0.5 | P10: 15 | Q10: 15 | R10: 0.5 | V10: 15 | W10: 15 | X10: 5.5 | AB10: 15 | AC10: 15 | AD10: 0.5 | AG10: =SUM(B10:AF10) -> 157.5 | AH10: =SUM(AG10-AG61) -> -8
A11: SRSW | D11: 1 | E11: 1 | J11: 1 | K11: 1 | P11: 1 | Q11: 1 | V11: 1 | W11: 1 | AB11: 1 | AC11: 1 | AG11: =SUM(B11:AF11) -> 10
AG12: =SUM(B12:AF12) -> 0
AG13: =SUM(B13:AF13) -> 0 | AH13: =SUM(AG13-AG67) -> 0
AG14: =SUM(B14:AF14) -> 0
A15: Michelle | B15: DS | C15: DS | H15: DS | I15: DS | N15: DS | O15: DS | T15: DS | U15: DS | Z15: 2 | AA15: 2 | AF15: 2 | AG15: =SUM(B15:AF15) -> 6
A16: McSporran | B16: 15 | C16: 15 | D16: 0.5 | H16: 15 | I16: 15 | J16: 5.5 | N16: 15 | O16: 15 | P16: 0.5 | T16: 15 | U16: 15 | V16: 0.5 | X16: 5 | Z16: 15 | AA16: 15 | AF16: 15 | AG16: =SUM(B16:AF16) -> 177 | AH16: =SUM(AG16-AG61) -> 11.5
A17: SRSW | B17: 1 | C17: 1 | H17: 1 | I17: 1 | N17: 1 | O17: 1 | T17: 1 | U17: 1 | AG17: =SUM(B17:AF17) -> 8
A18: Jack | F18: DS | G18: DS | L18: DS | M18: DS | R18: DS | S18: DS | X18: DS | Y18: DS | AD18: DS | AE18: DS | AG18: =SUM(B18:AF18) -> 0
A19: McMahon | F19: 15 | G19: 15 | H19: 0.5 | J19: 5 | L19: 15 | M19: 15 | N19: 0.5 | R19: 15 | S19: 15 | T19: 0.5 | X19: 15 | Y19: 15 | Z19: 0.5 | AD19: 15 | AE19: 15 | AF19: 0.5 | AG19: =SUM(B19:AF19) -> 157.5 | AH19: =SUM(AG19-AG61) -> -8
A20: Q. RSW | F20: 1 | G20: 1 | L20: 1 | M20: 1 | R20: 1 | S20: 1 | X20: 1 | Y20: 1 | AD20: 1 | AE20: 1 | AG20: =SUM(B20:AF20) -> 10
A21: Sarah | E21: 2 | F21: 2 | K21: DS | L21: DS | Q21: DS | R21: DS | W21: DS | X21: DS | AC21: DS | AD21: DS | AG21: =SUM(B21:AF21) -> 4
A22: Newson | E22: 15 | F22: 15 | K22: 15 | L22: 15 | M22: 0.5 | Q22: 15 | R22: 15 | S22: 0.5 | W22: 15 | X22: 15 | Y22: 0.5 | AC22: 15 | AD22: 15 | AE22: 0.5 | AG22: =SUM(B22:AF22) -> 152 | AH22: =SUM(AG22-AG61) -> -13.5
A23: Q. RSW | K23: 1 | L23: 1 | Q23: 1 | R23: 1 | W23: 1 | X23: 1 | AC23: 1 | AD23: 1 | AG23: =SUM(B23:AF23) -> 8
AG24: =SUM(B24:AF24) -> 0
AG25: =SUM(B25:AF25) -> 0 | AH25: =SUM(AG25-AG61) -> -165.5
AG26: =SUM(B26:AF26) -> 0
A27: Sam | C27: DS | D27: DS | I27: DS | J27: DS | O27: DS | P27: DS | U27: DS | V27: DS | X27: * | AA27: DS | AB27: DS | AG27: =SUM(B27:AF27) -> 0
A28: Lawrence | C28: 15 | D28: 15 | E28: 0.5 | I28: 15 | J28: 15 | K28: 0.5 | O28: 15 | P28: 15 | Q28: 0.5 | U28: 15 | V28: 15 | W28: 0.5 | X28: 4 | AA28: 15 | AB28: 15 | AC28: 0.5 | AG28: =SUM(B28:AF28) -> 156.5 | AH28: =SUM(AG28-AG61) -> -9
A29: UQ. RSW | C29: 1 | D29: 1 | I29: 1 | J29: 1 | O29: 1 | P29: 1 | U29: 1 | V29: 1 | AA29: 1 | AB29: 1 | AG29: =SUM(B29:AF29) -> 10
A30: Olivia | B30: DS | G30: DS | H30: DS | M30: DS | N30: DS | S30: DS | T30: DS | Y30: DS | Z30: DS | AE30: DS | AF30: DS | AG30: =SUM(B30:AF30) -> 0
A31: Machnik | B31: 15 | C31: 0.5 | G31: 15 | H31: 15 | I31: 0.5 | J31: 4 | M31: 15 | N31: 15 | O31: 0.5 | S31: 15 | T31: 15 | U31: 0.5 | X31: 4 | Y31: 15 | Z31: 15 | AA31: 0.5 | AE31: 15 | AF31: 15 | AG31: =SUM(B31:AF31) -> 175.5 | AH31: =SUM(AG31-AG61) -> 10
A32: UQ. RSW | B32: 1 | G32: 1 | H32: 1 | M32: 1 | N32: 1 | S32: 1 | T32: 1 | Y32: 1 | Z32: 1 | AE32: 1 | AF32: 1 | AG32: =SUM(B32:AF32) -> 11
A33: James | AG33: 0
A34: Logan | AG34: =SUM(B34:AF34) -> 0
A35: Bank | AG35: =SUM(B35:AF35) -> 0
AG36: 0
AG37: =SUM(B37:AF37) -> 0
AG38: =SUM(B38:AF38) -> 0
AG39: 0
AG40: =SUM(B40:AF40) -> 0
...

Sheet August
A1: Bodkin Way | B1: 1 | C1: 2 | D1: 3 | E1: 4 | F1: 5 | G1: 6 | H1: 7 | I1: 8 | J1: 9 | K1: 10 | L1: 11 | M1: 12 | N1: 13 | O1: 14 | P1: 15 | Q1: 16 | R1: 17 | S1: 18 | T1: 19 | U1: 20 | V1: 21 | W1: 22 | X1: 23 | Y1: 24 | Z1: 25 | AA1: 26 | AB1: 27 | AC1: 28 | AD1: 29 | AE1: 30 | AF1: 31 | AG1: ASI | AH1: Over/Under
A2: August | B2: S | C2: SU | D2: M | E2: T | F2: W | G2: TH | H2: F | I2: S | J2: SU | K2: M | L2: T | M2: W | N2: TH | O2: F | P2: S | Q2: SU | R2: M | S2: T | T2: W | U2: TH | V2: F | W2: S | X2: SU | Y2: M | Z2: T | AA2: W | AB2: TH | AC2: F | AD2: S | AE2: SU | AF2: M | AG2: =SUM(AG5,AG8,AG11,AG17,AG20,AG23,AG26,AG29,AG32,AG35,AG38,AG41,AG44,AG47,AG50,AG53,AG56,AG59) -> 55 | AH2: Hours
A3: Ellen | D3: A | E3: A | F3: A | G3: A | H3: A | K3: A | L3: A | M3: A | N3: A | O3: A | R3: A | S3: A | T3: A | U3: A | V3: A | Y3: A | Z3: A | AA3: A | AB3: A | AC3: A | AF3: A | AG3: =SUM(B3:AF3) -> 0
A4: Middleton | D4: 7.5 | E4: 7.5 | F4: 7.5 | G4: 7.5 | H4: 7.5 | K4: 7.5 | L4: 7.5 | M4: 7.5 | N4: 7.5 | O4: 7.5 | R4: 7.5 | S4: 7.5 | T4: 7.5 | U4: 7.5 | V4: 7.5 | Y4: 7.5 | Z4: 7.5 | AA4: 7.5 | AB4: 7.5 | AC4: 7.5 | AF4: 7.5 | AG4: =SUM(B4:AF4) -> 157.5
A5: RM | AG5: =SUM(B5:AF5) -> 0
A6: Charlotte | D6: A | E6: A | F6: A | G6: A | H6: A | K6: A | L6: A | M6: A | N6: A | O6: A | R6: A | S6: A | T6: A | U6: A | V6: A | Y6: A | Z6: A | AA6: A | AB6: A | AC6: A | AF6: A | AG6: =SUM(B6:AF6) -> 0
A7: Watson | D7: 7.5 | E7: 7.5 | F7: 7.5 | G7: 7.5 | H7: 7.5 | K7: 7.5 | L7: 7.5 | M7: 7.5 | N7: 7.5 | O7: 7.5 | R7: 7.5 | S7: 7.5 | T7: 7.5 | U7: 7.5 | V7: 7.5 | Y7: 7.5 | Z7: 7.5 | AA7: 7.5 | AB7: 7.5 | AC7: 7.5 | AF7: 7.5 | AG7: =SUM(B7:AF7) -> 157.5 | AH7: =SUM(AG7-AG61) -> -8
A8: DM | AG8: =SUM(B8:AF8) -> 0
A9: Philip | C9: DS | D9: DS | I9: DS | J9: DS | O9: DS | P9: DS | U9: DS | V9: DS | AA9: DS | AB9: DS | AG9: =SUM(B9:AF9) -> 0
A10: Thomas | C10: 15 | D10: 15 | E10: 0.5 | I10: 15 | J10: 15 | K10: 0.5 | N10: 5 | O10: 15 | P10: 15 | Q10: 0.5 | U10: 15 | V10: 15 | W10: 0.5 | AA10: 15 | AB10: 15 | AC10: 0.5 | AG10: =SUM(B10:AF10) -> 157.5 | AH10: =SUM(AG10-AG61) -> -8
A11: SRSW | C11: 1 | D11: 1 | I11: 1 | J11: 1 | O11: 1 | P11: 1 | U11: 1 | V11: 1 | AA11: 1 | AB11: 1 | AG11: =SUM(B11:AF11) -> 10
AG12: =SUM(B12:AF12) -> 0
AG13: =SUM(B13:AF13) -> 0 | AH13: =SUM(AG13-AG67) -> 0
AG14: =SUM(B14:AF14) -> 0
A15: Michelle | B15: 2 | G15: 2 | H15: 2 | M15: DS | N15: DS | S15: DS | T15: DS | Y15: DS | Z15: DS | AE15: DS | AF15: DS | AG15: =SUM(B15:AF15) -> 6
A16: McSporran | B16: 15 | G16: 15 | H16: 15 | M16: 15 | N16: 15 | O16: 0.5 | S16: 15 | T16: 15 | U16: 0.5 | Y16: 15 | Z16: 15 | AA16: 0.5 | AB16: 5 | AE16: 15 | AF16: 15 | AG16: =SUM(B16:AF16) -> 171.5 | AH16: =SUM(AG16-AG61) -> 6
A17: SRSW | M17: 1 | N17: 1 | S17: 1 | T17: 1 | Y17: 1 | Z17: 1 | AE17: 1 | AF17: 1 | AG17: =SUM(B17:AF17) -> 8
A18: Jack | E18: DS | F18: DS | K18: DS | L18: DS | Q18: DS | R18: DS | W18: 2 | X18: 2 | AC18: 2 | AD18: 2 | AG18: =SUM(B18:AF18) -> 8
A19: McMahon | E19: 15 | F19: 15 | G19: 0.5 | K19: 15 | L19: 15 | M19: 0.5 | N19: 5 | Q19: 15 | R19: 15 | S19: 0.5 | W19: 15 | X19: 15 | AC19: 15 | AD19: 15 | AG19: =SUM(B19:AF19) -> 156.5 | AH19: =SUM(AG19-AG61) -> -9
A20: Q. RSW | E20: 1 | F20: 1 | K20: 1 | L20: 1 | Q20: 1 | R20: 1 | AG20: =SUM(B20:AF20) -> 6
A21: Sarah | D21: DS | E21: DS | J21: DS | K21: DS | P21: DS | Q21: DS | V21: DS | W21: DS | AB21: DS | AC21: DS | AG21: =SUM(B21:AF21) -> 0
A22: Newson | D22: 15 | E22: 15 | F22: 0.5 | J22: 15 | K22: 15 | L22: 0.5 | N22: 4 | P22: 15 | Q22: 15 | R22: 0.5 | V22: 15 | W22: 15 | X22: 0.5 | AB22: 15 | AC22: 15 | AD22: 0.5 | AG22: =SUM(B22:AF22) -> 156.5 | AH22: =SUM(AG22-AG61) -> -9
A23: Q. RSW | D23: 1 | E23: 1 | J23: 1 | K23: 1 | P23: 1 | Q23: 1 | V23: 1 | W23: 1 | AB23: 1 | AC23: 1 | AG23: =SUM(B23:AF23) -> 10
AG24: =SUM(B24:AF24) -> 0
AG25: =SUM(B25:AF25) -> 0 | AH25: =SUM(AG25-AG61) -> -165.5
AG26: =SUM(B26:AF26) -> 0
A27: Sam | B27: DS | C27: DS | H27: DS | I27: DS | N27: DS | O27: DS | T27: DS | U27: DS | Z27: DS | AA27: DS | AF27: DS | AG27: =SUM(B27:AF27) -> 0
A28: Lawrence | B28: 15 | C28: 15 | D28: 0.5 | H28: 15 | I28: 15 | J28: 0.5 | N28: 15 | O28: 15 | P28: 0.5 | T28: 15 | U28: 15 | V28: 0.5 | Z28: 15 | AA28: 15 | AB28: 4.5 | AF28: 15 | AG28: =SUM(B28:AF28) -> 171.5 | AH28: =SUM(AG28-AG61) -> 6
A29: UQ. RSW | B29: 1 | C29: 1 | H29: 1 | I29: 1 | N29: 1 | O29: 1 | T29: 1 | U29: 1 | Z29: 1 | AA29: 1 | AF29: 1 | AG29: =SUM(B29:AF29) -> 11
A30: Olivia | F30: DS | G30: DS | L30: DS | M30: DS | R30: DS | S30: DS | X30: DS | Y30: DS | AD30: DS | AE30: DS | AG30: =SUM(B30:AF30) -> 0
A31: Machnik | F31: 15 | G31: 15 | H31: 0.5 | L31: 15 | M31: 15 | N31: 4.5 | R31: 15 | S31: 15 | T31: 0.5 | X31: 15 | Y31: 15 | Z31: 0.5 | AB31: 4 | AD31: 15 | AE31: 15 | AF31: 0.5 | AG31: =SUM(B31:AF31) -> 160.5 | AH31: =SUM(AG31-AG61) -> -5
A32: UQ. RSW | F32: 1 | G32: 1 | L32: 1 | M32: 1 | R32: 1 | S32: 1 | X32: 1 | Y32: 1 | AD32: 1 | AE32: 1 | AG32: =SUM(B32:AF32) -> 10
A33: James | AG33: 0
A34: Logan | AG34: =SUM(B34:AF34) -> 0
A35: Bank | AG35: =SUM(B35:AF35) -> 0
AG36: 0
AG37: =SUM(B37:AF37) -> 0
AG38: =SUM(B38:AF38) -> 0
AG39: 0
AG40: =SUM(B40:AF40) -> 0
...

Sheet September
A1: Bodkin Way | B1: 1 | C1: 2 | D1: 3 | E1: 4 | F1: 5 | G1: 6 | H1: 7 | I1: 8 | J1: 9 | K1: 10 | L1: 11 | M1: 12 | N1: 13 | O1: 14 | P1: 15 | Q1: 16 | R1: 17 | S1: 18 | T1: 19 | U1: 20 | V1: 21 | W1: 22 | X1: 23 | Y1: 24 | Z1: 25 | AA1: 26 | AB1: 27 | AC1: 28 | AD1: 29 | AE1: 30 | AF1: ASI | AG1: Over/Under
A2: Sept. | B2: T | C2: W | D2: TH | E2: F | F2: S | G2: SU | H2: M | I2: T | J2: W | K2: TH | L2: F | M2: S | N2: SU | O2: M | P2: T | Q2: W | R2: TH | S2: F | T2: S | U2: SU | V2: M | W2: T | X2: W | Y2: TH | Z2: F | AA2: S | AB2: SU | AC2: M | AD2: T | AE2: W | AF2: =SUM(AF5,AF8,AF11,AF17,AF20,AF23,AF26,AF29,AF32,AF35,AF38,AF41,AF44,AF47,AF50,AF53,AF56,AF59,AF62,AF65) -> 60 | AG2: Hours
A3: Ellen | B3: A | C3: A | D3: A | E3: A | H3: A | I3: A | J3: A | K3: A | L3: A | O3: A | P3: A | Q3: A | R3: A | S3: A | V3: A | W3: A | X3: A | Y3: A | Z3: A | AC3: A | AD3: A | AE3: A | AF3: =SUM(B3:AE3) -> 0
A4: Middleton | B4: 7.5 | C4: 7.5 | D4: 7.5 | E4: 7.5 | H4: 7.5 | I4: 7.5 | J4: 7.5 | K4: 7.5 | L4: 7.5 | O4: 7.5 | P4: 7.5 | Q4: 7.5 | R4: 7.5 | S4: 7.5 | V4: 7.5 | W4: 7.5 | X4: 7.5 | Y4: 7.5 | Z4: 7.5 | AC4: 7.5 | AD4: 7.5 | AE4: 7.5 | AF4: =SUM(B4:AE4) -> 165
A5: RM | AF5: =SUM(B5:AE5) -> 0
A6: Charlotte | B6: A | C6: A | D6: A | E6: A | H6: A | I6: A | J6: A | K6: A | L6: A | O6: A | P6: A | Q6: A | R6: A | S6: A | V6: A | W6: A | X6: A | Y6: A | Z6: A | AC6: A | AD6: A | AE6: A | AF6: =SUM(B6:AE6) -> 0
A7: Watson | B7: 7.5 | C7: 7.5 | D7: 7.5 | E7: 7.5 | H7: 7.5 | I7: 7.5 | J7: 7.5 | K7: 7.5 | L7: 7.5 | O7: 7.5 | P7: 7.5 | Q7: 7.5 | R7: 7.5 | S7: 7.5 | V7: 7.5 | W7: 7.5 | X7: 7.5 | Y7: 7.5 | Z7: 7.5 | AC7: 7.5 | AD7: 7.5 | AE7: 7.5 | AF7: =SUM(B7:AE7) -> 165 | AG7: =SUM(AF7-AF67) -> 5
A8: DM | AF8: =SUM(B8:AE8) -> 0
A9: Philip | B9: DS | C9: DS | H9: DS | I9: DS | N9: DS | O9: DS | T9: DS | U9: DS | Z9: DS | AA9: DS | AF9: =SUM(B9:AE9) -> 0
A10: Thomas | B10: 15 | C10: 15 | D10: 0.5 | H10: 15 | I10: 15 | J10: 0.5 | K10: 5 | N10: 15 | O10: 15 | P10: 0.5 | T10: 15 | U10: 15 | V10: 0.5 | Y10: 5 | Z10: 15 | AA10: 15 | AB10: 0.5 | AF10: =SUM(B10:AE10) -> 162.5 | AG10: =SUM(AF10-AF67) -> 2.5
A11: SRSW | B11: 1 | C11: 1 | H11: 1 | I11: 1 | N11: 1 | O11: 1 | T11: 1 | U11: 1 | Z11: 1 | AA11: 1 | AF11: =SUM(B11:AE11) -> 10
AF12: =SUM(B12:AE12) -> 0
AF13: =SUM(B13:AE13) -> 0 | AG13: 2
AF14: =SUM(B14:AE14) -> 0
A15: Michelle | F15: DS | G15: DS | L15: DS | M15: DS | R15: DS | S15: DS | X15: DS | Y15: DS | AD15: DS | AE15: DS | AF15: =SUM(B15:AE15) -> 0
A16: McSporran | F16: 15 | G16: 15 | H16: 0.5 | K16: 5 | L16: 15 | M16: 15 | N16: 0.5 | R16: 15 | S16: 15 | T16: 0.5 | X16: 15 | Y16: 15 | Z16: 0.5 | AD16: 15 | AE16: 15 | AF16: =SUM(B16:AE16) -> 157 | AG16: =SUM(AF16-AF67) -> -3
A17: SRSW | F17: 1 | G17: 1 | L17: 1 | M17: 1 | R17: 1 | S17: 1 | X17: 1 | Y17: 1 | AD17: 1 | AE17: 1 | AF17: =SUM(B17:AE17) -> 10
A18: Jack | D18: DS | E18: DS | J18: DS | K18: DS | P18: DS | Q18: DS | V18: DS | W18: DS | AB18: DS | AC18: DS | AF18: =SUM(B18:AE18) -> 0
A19: McMahon | D19: 15 | E19: 15 | F19: 0.5 | J19: 15 | K19: 15 | L19: 0.5 | P19: 15 | Q19: 15 | R19: 0.5 | V19: 15 | W19: 15 | X19: 0.5 | Y19: 5 | AB19: 15 | AC19: 15 | AD19: 0.5 | AF19: =SUM(B19:AE19) -> 157.5 | AG19: =SUM(AF19-AF67) -> -2.5
A20: Q. RSW | D20: 1 | E20: 1 | J20: 1 | K20: 1 | P20: 1 | Q20: 1 | V20: 1 | W20: 1 | AB20: 1 | AC20: 1 | AF20: =SUM(B20:AE20) -> 10
A21: Sarah | C21: DS | D21: DS | I21: DS | J21: DS | O21: DS | P21: DS | U21: DS | V21: DS | AA21: DS | AB21: DS | AF21: =SUM(B21:AE21) -> 0
A22: Newson | C22: 15 | D22: 15 | E22: 0.5 | I22: 15 | J22: 15 | K22: 4.5 | O22: 15 | P22: 15 | Q22: 0.5 | U22: 15 | V22: 15 | W22: 0.5 | Y22: 4 | AA22: 15 | AB22: 15 | AC22: 0.5 | AF22: =SUM(B22:AE22) -> 160.5 | AG22: =SUM(AF22-AF67) -> 0.5
A23: Q. RSW | C23: 1 | D23: 1 | I23: 1 | J23: 1 | O23: 1 | P23: 1 | U23: 1 | V23: 1 | AA23: 1 | AB23: 1 | AF23: =SUM(B23:AE23) -> 10
AF24: =SUM(B24:AE24) -> 0
AF25: =SUM(B25:AE25) -> 0 | AG25: =SUM(AF25-AF67) -> -160
AF26: =SUM(B26:AE26) -> 0
A27: Sam | B27: DS | G27: DS | H27: DS | M27: DS | N27: DS | S27: DS | T27: DS | Y27: DS | Z27: DS | AE27: DS | AF27: =SUM(B27:AE27) -> 0
A28: Lawrence | B28: 15 | C28: 0.5 | G28: 15 | H28: 15 | I28: 0.5 | K28: 4 | M28: 15 | N28: 15 | O28: 0.5 | S28: 15 | T28: 15 | U28: 0.5 | Y28: 15 | Z28: 15 | AA28: 0.5 | AE28: 15 | AF28: =SUM(B28:AE28) -> 156.5 | AG28: =SUM(AF28-AF67) -> -3.5
A29: UQ. RSW | B29: 1 | G29: 1 | H29: 1 | M29: 1 | N29: 1 | S29: 1 | T29: 1 | Y29: 1 | Z29: 1 | AE29: 1 | AF29: =SUM(B29:AE29) -> 10
A30: Olivia | E30: DS | F30: DS | K30: DS | L30: DS | Q30: DS | R30: DS | W30: DS | X30: DS | AC30: DS | AD30: DS | AF30: =SUM(B30:AE30) -> 0
A31: Machnik | E31: 15 | F31: 15 | G31: 0.5 | K31: 15 | L31: 15 | M31: 0.5 | Q31: 15 | R31: 15 | S31: 0.5 | W31: 15 | X31: 15 | Y31: 4.5 | AC31: 15 | AD31: 15 | AE31: 0.5 | AF31: =SUM(B31:AE31) -> 156.5 | AG31: =SUM(AF31-AF67) -> -3.5
A32: UQ. RSW | E32: 1 | F32: 1 | K32: 1 | L32: 1 | Q32: 1 | R32: 1 | W32: 1 | X32: 1 | AC32: 1 | AD32: 1 | AF32: =SUM(B32:AE32) -> 10
A33: James | AF33: =SUM(B33:AE33) -> 0
A34: Logan | AF34: =SUM(B34:AE34) -> 0
A35: Bank | AF35: =SUM(B35:AE35) -> 0
AF36: =SUM(B36:AE36) -> 0
AF37: =SUM(B37:AE37) -> 0
AF38: =SUM(B38:AE38) -> 0
AF39: =SUM(B39:AE39) -> 0
AF40: =SUM(B40:AE40) -> 0
...

Sheet October
A1: Bodkin Way | B1: 1 | C1: 2 | D1: 3 | E1: 4 | F1: 5 | G1: 6 | H1: 7 | I1: 8 | J1: 9 | K1: 10 | L1: 11 | M1: 12 | N1: 13 | O1: 14 | P1: 15 | Q1: 16 | R1: 17 | S1: 18 | T1: 19 | U1: 20 | V1: 21 | W1: 22 | X1: 23 | Y1: 24 | Z1: 25 | AA1: 26 | AB1: 27 | AC1: 28 | AD1: 29 | AE1: 30 | AF1: 31 | AG1: ASI | AH1: Over/Under
A2: Oct. | B2: TH | C2: F | D2: S | E2: SU | F2: M | G2: T | H2: W | I2: TH | J2: F | K2: S | L2: SU | M2: M | N2: T | O2: W | P2: TH | Q2: F | R2: S | S2: SU | T2: M | U2: T | V2: W | W2: TH | X2: F | Y2: S | Z2: SU | AA2: M | AB2: T | AC2: W | AD2: TH | AE2: F | AF2: S | AG2: =SUM(AG5,AG8,AG11,AG17,AG20,AG23,AG26,AG29,AG32,AG35,AG38,AG41,AG44,AG47,AG50,AG53,AG56,AG59) -> 60 | AH2: Hours
A3: Ellen | B3: A | C3: A | F3: A | G3: A | H3: A | I3: A | J3: A | M3: A | N3: A | O3: A | P3: A | Q3: A | T3: A | U3: A | V3: A | W3: A | X3: A | AA3: A | AB3: A | AC3: A | AD3: A | AE3: A | AG3: =SUM(B3:AF3) -> 0
A4: Middleton | B4: 7.5 | C4: 7.5 | F4: 7.5 | G4: 7.5 | H4: 7.5 | I4: 7.5 | J4: 7.5 | M4: 7.5 | N4: 7.5 | O4: 7.5 | P4: 7.5 | Q4: 7.5 | T4: 7.5 | U4: 7.5 | V4: 7.5 | W4: 7.5 | X4: 7.5 | AA4: 7.5 | AB4: 7.5 | AC4: 7.5 | AD4: 7.5 | AE4: 7.5 | AG4: =SUM(B4:AF4) -> 165
A5: RM | AG5: =SUM(B5:AF5) -> 0
A6: Charlotte | B6: A | C6: A | F6: A | G6: A | H6: A | I6: A | J6: A | M6: A | N6: A | O6: A | P6: A | Q6: A | T6: A | U6: A | V6: A | W6: A | X6: A | AA6: A | AB6: A | AC6: A | AD6: A | AE6: A | AG6: =SUM(B6:AF6) -> 0
A7: Watson | B7: 7.5 | C7: 7.5 | F7: 7.5 | G7: 7.5 | H7: 7.5 | I7: 7.5 | J7: 7.5 | M7: 7.5 | N7: 7.5 | O7: 7.5 | P7: 7.5 | Q7: 7.5 | T7: 7.5 | U7: 7.5 | V7: 7.5 | W7: 7.5 | X7: 7.5 | AA7: 7.5 | AB7: 7.5 | AC7: 7.5 | AD7: 7.5 | AE7: 7.5 | AG7: =SUM(B7:AF7) -> 165 | AH7: =SUM(AG7-AG61) -> -0.5
A8: DM | AG8: =SUM(B8:AF8) -> 0
A9: Philip | B9: DS | C9: DS | H9: DS | I9: DS | N9: DS | O9: DS | T9: DS | U9: DS | Z9: DS | AA9: DS | AF9: DS | AG9: =SUM(B9:AF9) -> 0
A10: Thomas | B10: 15 | C10: 15 | D10: 0.5 | H10: 15 | I10: 15 | J10: 0.5 | N10: 15 | O10: 15 | P10: 0.5 | T10: 15 | U10: 15 | V10: 0.5 | W10: 5 | Z10: 15 | AA10: 15 | AB10: 0.5 | AF10: 15 | AG10: =SUM(B10:AF10) -> 172.5 | AH10: =SUM(AG10-AG61) -> 7
A11: SRSW | B11: 1 | C11: 1 | H11: 1 | I11: 1 | N11: 1 | O11: 1 | T11: 1 | U11: 1 | Z11: 1 | AA11: 1 | AF11: 1 | AG11: =SUM(B11:AF11) -> 11
AG12: =SUM(B12:AF12) -> 0
AG13: =SUM(B13:AF13) -> 0 | AH13: =SUM(AG13-AG58) -> 0
AG14: =SUM(B14:AF14) -> 0
A15: Michelle | F15: DS | G15: DS | L15: DS | M15: DS | R15: DS | S15: DS | X15: DS | Y15: DS | AD15: DS | AE15: DS | AG15: =SUM(B15:AF15) -> 0
A16: McSporran | F16: 15 | G16: 15 | H16: 0.5 | I16: 5 | L16: 15 | M16: 15 | N16: 0.5 | R16: 15 | S16: 15 | T16: 0.5 | W16: 5 | X16: 15 | Y16: 15 | Z16: 0.5 | AD16: 15 | AE16: 15 | AF16: 0.5 | AG16: =SUM(B16:AF16) -> 162.5 | AH16: =SUM(AG16-AG61) -> -3
A17: SRSW | F17: 1 | G17: 1 | L17: 1 | M17: 1 | R17: 1 | S17: 1 | X17: 1 | Y17: 1 | AD17: 1 | AE17: 1 | AG17: =SUM(B17:AF17) -> 10
A18: Jack | D18: DS | E18: DS | J18: DS | K18: DS | P18: 2 | Q18: 2 | V18: DS | W18: DS | AB18: DS | AC18: DS | AG18: =SUM(B18:AF18) -> 4
A19: McMahon | D19: 15 | E19: 15 | F19: 0.5 | I19: 5 | J19: 15 | K19: 15 | L19: 0.5 | P19: 15 | Q19: 15 | R19: * | V19: 15 | W19: 15 | X19: 0.5 | AB19: 15 | AC19: 15 | AD19: 0.5 | AG19: =SUM(B19:AF19) -> 157 | AH19: =SUM(AG19-AG61) -> -8.5
A20: Q. RSW | D20: 1 | E20: 1 | J20: 1 | K20: 1 | V20: 1 | W20: 1 | AB20: 1 | AC20: 1 | AG20: =SUM(B20:AF20) -> 8
A21: Sarah | C21: DS | D21: DS | I21: DS | J21: DS | O21: DS | P21: DS | U21: DS | V21: DS | AA21: DS | AB21: DS | AG21: =SUM(B21:AF21) -> 0
A22: Newson | C22: 15 | D22: 15 | E22: 0.5 | I22: 15 | J22: 15 | K22: 0.5 | O22: 15 | P22: 15 | Q22: 0.5 | U22: 15 | V22: 15 | W22: 4.5 | AA22: 15 | AB22: 15 | AC22: 0.5 | AG22: =SUM(B22:AF22) -> 156.5 | AH22: =SUM(AG22-AG61) -> -9
A23: Q. RSW | C23: 1 | D23: 1 | I23: 1 | J23: 1 | O23: 1 | P23: 1 | U23: 1 | V23: 1 | AA23: 1 | AB23: 1 | AG23: =SUM(B23:AF23) -> 10
AG24: =SUM(B24:AF24) -> 0
AG25: =SUM(B25:AF25) -> 0 | AH25: =SUM(AG25-AG61) -> -165.5
AG26: =SUM(B26:AF26) -> 0
A27: Sam | B27: DS | G27: DS | H27: DS | M27: DS | N27: DS | S27: DS | T27: DS | Y27: DS | Z27: DS | AE27: DS | AF27: DS | AG27: =SUM(B27:AF27) -> 0
A28: Lawrence | B28: 15 | C28: 0.5 | G28: 15 | H28: 15 | I28: 4.5 | M28: 15 | N28: 15 | O28: 0.5 | S28: 15 | T28: 15 | U28: 0.5 | W28: 4 | Y28: 15 | Z28: 15 | AA28: 0.5 | AE28: 15 | AF28: 15 | AG28: =SUM(B28:AF28) -> 175.5 | AH28: =SUM(AG28-AG61) -> 10
A29: UQ. RSW | B29: 1 | G29: 1 | H29: 1 | M29: 1 | N29: 1 | S29: 1 | T29: 1 | Y29: 1 | Z29: 1 | AE29: 1 | AF29: 1 | AG29: =SUM(B29:AF29) -> 11
A30: Olivia | E30: DS | F30: DS | K30: DS | L30: DS | Q30: DS | R30: DS | W30: DS | X30: DS | AC30: DS | AD30: DS | AG30: =SUM(B30:AF30) -> 0
A31: Machnik | E31: 15 | F31: 15 | G31: 0.5 | I31: 4 | K31: 15 | L31: 15 | M31: 0.5 | Q31: 15 | R31: 15 | S31: 0.5 | W31: 15 | X31: 15 | Y31: 0.5 | AC31: 15 | AD31: 15 | AE31: 0.5 | AG31: =SUM(B31:AF31) -> 156.5 | AH31: =SUM(AG31-AG61) -> -9
A32: UQ. RSW | E32: 1 | F32: 1 | K32: 1 | L32: 1 | Q32: 1 | R32: 1 | W32: 1 | X32: 1 | AC32: 1 | AD32: 1 | AG32: =SUM(B32:AF32) -> 10
A33: James | AG33: 0
A34: Logan | AG34: =SUM(B34:AF34) -> 0
A35: Bank | AG35: =SUM(B35:AF35) -> 0
AG36: 0
AG37: =SUM(B37:AF37) -> 0
AG38: =SUM(B38:AF38) -> 0
AG39: 0
AG40: =SUM(B40:AF40) -> 0
...

Sheet November
A1: Bodkin Way | B1: 1 | C1: 2 | D1: 3 | E1: 4 | F1: 5 | G1: 6 | H1: 7 | I1: 8 | J1: 9 | K1: 10 | L1: 11 | M1: 12 | N1: 13 | O1: 14 | P1: 15 | Q1: 16 | R1: 17 | S1: 18 | T1: 19 | U1: 20 | V1: 21 | W1: 22 | X1: 23 | Y1: 24 | Z1: 25 | AA1: 26 | AB1: 27 | AC1: 28 | AD1: 29 | AE1: 30 | AF1: ASI | AG1: Over/Under
A2: Nov. | B2: SU | C2: M | D2: T | E2: W | F2: TH | G2: F | H2: S | I2: SU | J2: M | K2: T | L2: W | M2: TH | N2: F | O2: S | P2: SU | Q2: M | R2: T | S2: W | T2: TH | U2: F | V2: S | W2: SU | X2: M | Y2: T | Z2: W | AA2: TH | AB2: F | AC2: S | AD2: SU | AE2: M | AF2: =SUM(AF5,AF8,AF11,AF17,AF20,AF23,AF26,AF29,AF32,AF35,AF38,AF41,AF44,AF47,AF50,AF53,AF56,AF59,AF62,AF65) -> 58 | AG2: Hours
A3: Ellen | C3: A | D3: A | E3: A | F3: A | G3: A | J3: A | K3: A | L3: A | M3: A | N3: A | Q3: A | R3: A | S3: A | T3: A | U3: A | X3: A | Y3: A | Z3: A | AA3: A | AB3: A | AE3: A | AF3: =SUM(B3:AE3) -> 0
A4: Middleton | C4: 7.5 | D4: 7.5 | E4: 7.5 | F4: 7.5 | G4: 7.5 | J4: 7.5 | K4: 7.5 | L4: 7.5 | M4: 7.5 | N4: 7.5 | Q4: 7.5 | R4: 7.5 | S4: 7.5 | T4: 7.5 | U4: 7.5 | X4: 7.5 | Y4: 7.5 | Z4: 7.5 | AA4: 7.5 | AB4: 7.5 | AE4: 7.5 | AF4: =SUM(B4:AE4) -> 157.5
A5: RM | AF5: =SUM(B5:AE5) -> 0
A6: Charlotte | C6: A | D6: A | E6: A | F6: A | G6: A | J6: A | K6: A | L6: A | M6: A | N6: A | Q6: A | R6: A | S6: A | T6: A | U6: A | X6: A | Y6: A | Z6: A | AA6: A | AB6: A | AE6: A | AF6: =SUM(B6:AE6) -> 0
A7: Watson | C7: 7.5 | D7: 7.5 | E7: 7.5 | F7: 7.5 | G7: 7.5 | J7: 7.5 | K7: 7.5 | L7: 7.5 | M7: 7.5 | N7: 7.5 | Q7: 7.5 | R7: 7.5 | S7: 7.5 | T7: 7.5 | U7: 7.5 | X7: 7.5 | Y7: 7.5 | Z7: 7.5 | AA7: 7.5 | AB7: 7.5 | AE7: 7.5 | AF7: =SUM(B7:AE7) -> 157.5 | AG7: =SUM(AF7-AF67) -> -2.5
A8: DM | AF8: =SUM(B8:AE8) -> 0
A9: Philip | B9: DS | G9: DS | H9: DS | M9: DS | N9: DS | S9: DS | T9: DS | Y9: DS | Z9: DS | AE9: DS | AF9: =SUM(B9:AE9) -> 0
A10: Thomas | B10: 15 | C10: 0.5 | G10: 15 | H10: 15 | I10: 0.5 | M10: 15 | N10: 15 | O10: 0.5 | S10: 15 | T10: 15 | U10: 0.5 | Y10: 15 | Z10: 15 | AA10: 5.5 | AE10: 15 | AF10: =SUM(B10:AE10) -> 157.5 | AG10: =SUM(AF10-AF67) -> -2.5
A11: SRSW | B11: 1 | G11: 1 | H11: 1 | M11: 1 | N11: 1 | S11: 1 | T11: 1 | Y11: 1 | Z11: 1 | AE11: 1 | AF11: =SUM(B11:AE11) -> 10
AF12: =SUM(B12:AE12) -> 0
AF13: =SUM(B13:AE13) -> 0 | AG13: 2
AF14: =SUM(B14:AE14) -> 0
A15: Michelle | E15: DS | F15: DS | K15: DS | L15: DS | Q15: DS | R15: DS | W15: DS | X15: DS | AC15: DS | AD15: DS | AF15: =SUM(B15:AE15) -> 0
A16: McSporran | E16: 15 | F16: 15 | G16: 0.5 | K16: 15 | L16: 15 | M16: 5.5 | Q16: 15 | R16: 15 | S16: 0.5 | W16: 15 | X16: 15 | Y16: 0.5 | AA16: 5 | AC16: 15 | AD16: 15 | AE16: 0.5 | AF16: =SUM(B16:AE16) -> 162.5 | AG16: =SUM(AF16-AF67) -> 2.5
A17: SRSW | E17: 1 | F17: 1 | K17: 1 | L17: 1 | Q17: 1 | R17: 1 | W17: 1 | X17: 1 | AC17: 1 | AD17: 1 | AF17: =SUM(B17:AE17) -> 10
A18: Jack | C18: DS | D18: DS | I18: DS | J18: DS | O18: DS | P18: DS | U18: 2 | V18: 2 | AA18: DS | AB18: DS | AF18: =SUM(B18:AE18) -> 4
A19: McMahon | C19: 15 | D19: 15 | E19: 0.5 | I19: 15 | J19: 15 | K19: 0.5 | M19: 5 | O19: 15 | P19: 15 | Q19: 0.5 | U19: 15 | V19: 15 | AA19: 15 | AB19: 15 | AC19: 0.5 | AF19: =SUM(B19:AE19) -> 157 | AG19: =SUM(AF19-AF67) -> -3
A20: Q. RSW | C20: 1 | D20: 1 | I20: 1 | J20: 1 | O20: 1 | P20: 1 | AA20: 1 | AB20: 1 | AF20: =SUM(B20:AE20) -> 8
A21: Sarah | B21: DS | C21: DS | H21: DS | I21: DS | N21: DS | O21: DS | T21: DS | U21: DS | Z21: DS | AA21: DS | AF21: =SUM(B21:AE21) -> 0
A22: Newson | B22: 15 | C22: 15 | D22: 0.5 | H22: 15 | I22: 15 | J22: 0.5 | M22: 4 | N22: 15 | O22: 15 | P22: 0.5 | T22: 15 | U22: 15 | V22: 0.5 | Z22: 15 | AA22: 15 | AB22: 0.5 | AF22: =SUM(B22:AE22) -> 156.5 | AG22: =SUM(AF22-AF67) -> -3.5
A23: Q. RSW | B23: 1 | C23: 1 | H23: 1 | I23: 1 | N23: 1 | O23: 1 | T23: 1 | U23: 1 | Z23: 1 | AA23: 1 | AF23: =SUM(B23:AE23) -> 10
AF24: =SUM(B24:AE24) -> 0
AF25: =SUM(B25:AE25) -> 0 | AG25: =SUM(AF25-AF67) -> -160
AF26: =SUM(B26:AE26) -> 0
A27: Sam | F27: DS | G27: DS | L27: DS | M27: DS | R27: DS | S27: DS | X27: DS | Y27: DS | AD27: DS | AE27: DS | AF27: =SUM(B27:AE27) -> 0
A28: Lawrence | F28: 15 | G28: 15 | H28: 0.5 | L28: 15 | M28: 15 | N28: 0.5 | R28: 15 | S28: 15 | T28: 0.5 | X28: 15 | Y28: 15 | Z28: 0.5 | AA28: 4 | AD28: 15 | AE28: 15 | AF28: =SUM(B28:AE28) -> 156 | AG28: =SUM(AF28-AF67) -> -4
A29: UQ. RSW | F29: 1 | G29: 1 | L29: 1 | M29: 1 | R29: 1 | S29: 1 | X29: 1 | Y29: 1 | AD29: 1 | AE29: 1 | AF29: =SUM(B29:AE29) -> 10
A30: Olivia | D30: DS | E30: DS | J30: DS | K30: DS | P30: DS | Q30: DS | V30: DS | W30: DS | AB30: DS | AC30: DS | AF30: =SUM(B30:AE30) -> 0
A31: Machnik | D31: 15 | E31: 15 | F31: 0.5 | J31: 15 | K31: 15 | L31: 0.5 | M31: 4 | P31: 15 | Q31: 15 | R31: 0.5 | V31: 15 | W31: 15 | X31: 0.5 | AA31: 4 | AB31: 15 | AC31: 15 | AD31: 0.5 | AF31: =SUM(B31:AE31) -> 160.5 | AG31: =SUM(AF31-AF67) -> 0.5
A32: UQ. RSW | D32: 1 | E32: 1 | J32: 1 | K32: 1 | P32: 1 | Q32: 1 | V32: 1 | W32: 1 | AB32: 1 | AC32: 1 | AF32: =SUM(B32:AE32) -> 10
A33: James | AF33: =SUM(B33:AE33) -> 0
A34: Logan | AF34: =SUM(B34:AE34) -> 0
A35: Bank | AF35: =SUM(B35:AE35) -> 0
AF36: =SUM(B36:AE36) -> 0
AF37: =SUM(B37:AE37) -> 0
AF38: =SUM(B38:AE38) -> 0
AF39: =SUM(B39:AE39) -> 0
AF40: =SUM(B40:AE40) -> 0
...

Sheet December
A1: Bodkin Way | B1: 1 | C1: 2 | D1: 3 | E1: 4 | F1: 5 | G1: 6 | H1: 7 | I1: 8 | J1: 9 | K1: 10 | L1: 11 | M1: 12 | N1: 13 | O1: 14 | P1: 15 | Q1: 16 | R1: 17 | S1: 18 | T1: 19 | U1: 20 | V1: 21 | W1: 22 | X1: 23 | Y1: 24 | Z1: 25 | AA1: 26 | AB1: 27 | AC1: 28 | AD1: 29 | AE1: 30 | AF1: 31 | AG1: ASI | AH1: Over/Under
A2: Dec. | B2: T | C2: W | D2: TH | E2: F | F2: S | G2: SU | H2: M | I2: T | J2: W | K2: TH | L2: F | M2: S | N2: SU | O2: M | P2: T | Q2: W | R2: TH | S2: F | T2: S | U2: SU | V2: M | W2: T | X2: W | Y2: TH | Z2: F | AA2: S | AB2: SU | AC2: M | AD2: T | AE2: W | AF2: TH | AG2: =SUM(AG5,AG8,AG11,AG17,AG20,AG23,AG26,AG29,AG32,AG35,AG38,AG41,AG44,AG47,AG50,AG53,AG56,AG59) -> 62 | AH2: Hours
A3: Ellen | B3: A | C3: A | D3: A | E3: A | H3: A | I3: A | J3: A | K3: A | L3: A | O3: A | P3: A | Q3: A | R3: A | S3: A | V3: A | W3: A | X3: A | Y3: A | Z3: A | AC3: A | AD3: A | AE3: A | AF3: A | AG3: =SUM(B3:AF3) -> 0
A4: Middleton | B4: 7.5 | C4: 7.5 | D4: 7.5 | E4: 7.5 | H4: 7.5 | I4: 7.5 | J4: 7.5 | K4: 7.5 | L4: 7.5 | O4: 7.5 | P4: 7.5 | Q4: 7.5 | R4: 7.5 | S4: 7.5 | V4: 7.5 | W4: 7.5 | X4: 7.5 | Y4: 7.5 | Z4: 7.5 | AC4: 7.5 | AD4: 7.5 | AE4: 7.5 | AF4: 7.5 | AG4: =SUM(B4:AF4) -> 172.5
A5: RM | AG5: =SUM(B5:AF5) -> 0
A6: Charlotte | B6: A | C6: A | D6: A | E6: A | H6: A | I6: A | J6: A | K6: A | L6: A | O6: A | P6: A | Q6: A | R6: A | S6: A | V6: A | W6: A | X6: A | Y6: A | Z6: A | AC6: A | AD6: A | AE6: A | AF6: A | AG6: =SUM(B6:AF6) -> 0
A7: Watson | B7: 7.5 | C7: 7.5 | D7: 7.5 | E7: 7.5 | H7: 7.5 | I7: 7.5 | J7: 7.5 | K7: 7.5 | L7: 7.5 | O7: 7.5 | P7: 7.5 | Q7: 7.5 | R7: 7.5 | S7: 7.5 | V7: 7.5 | W7: 7.5 | X7: 7.5 | Y7: 7.5 | Z7: 7.5 | AC7: 7.5 | AD7: 7.5 | AE7: 7.5 | AF7: 7.5 | AG7: =SUM(B7:AF7) -> 172.5 | AH7: =SUM(AG7-AG61) -> 7
A8: DM | AG8: =SUM(B8:AF8) -> 0
A9: Philip | B9: DS | G9: DS | H9: DS | M9: DS | N9: DS | S9: DS | T9: DS | Y9: DS | Z9: DS | AE9: DS | AF9: DS | AG9: =SUM(B9:AF9) -> 0
A10: Thomas | B10: 15 | C10: 0.5 | G10: 15 | H10: 15 | I10: 0.5 | K10: 5 | M10: 15 | N10: 15 | O10: 0.5 | S10: 15 | T10: 15 | U10: 0.5 | Y10: 15 | Z10: 15 | AA10: 0.5 | AE10: 15 | AF10: 15 | AG10: =SUM(B10:AF10) -> 172.5 | AH10: =SUM(AG10-AG61) -> 7
A11: SRSW | B11: 1 | G11: 1 | H11: 1 | M11: 1 | N11: 1 | S11: 1 | T11: 1 | Y11: 1 | Z11: 1 | AE11: 1 | AF11: 1 | AG11: =SUM(B11:AF11) -> 11
AG12: =SUM(B12:AF12) -> 0
AG13: =SUM(B13:AF13) -> 0 | AH13: =SUM(AG13-AG58) -> 0
AG14: =SUM(B14:AF14) -> 0
A15: Michelle | E15: DS | F15: DS | K15: DS | L15: DS | Q15: DS | R15: DS | W15: DS | X15: DS | AC15: DS | AD15: DS | AG15: =SUM(B15:AF15) -> 0
A16: McSporran | E16: 15 | F16: 15 | G16: 0.5 | K16: 15 | L16: 15 | M16: 0.5 | Q16: 15 | R16: 15 | S16: 0.5 | W16: 15 | X16: 15 | Y16: 5.5 | AC16: 15 | AD16: 15 | AE16: 0.5 | AG16: =SUM(B16:AF16) -> 157.5 | AH16: =SUM(AG16-AG61) -> -8
A17: SRSW | E17: 1 | F17: 1 | K17: 1 | L17: 1 | Q17: 1 | R17: 1 | W17: 1 | X17: 1 | AC17: 1 | AD17: 1 | AG17: =SUM(B17:AF17) -> 10
A18: Jack | C18: DS | D18: DS | I18: DS | J18: DS | O18: DS | P18: DS | U18: DS | V18: DS | AA18: DS | AB18: DS | AG18: =SUM(B18:AF18) -> 0
A19: McMahon | C19: 15 | D19: 15 | E19: 0.5 | I19: 15 | J19: 15 | K19: 5.5 | O19: 15 | P19: 15 | Q19: 0.5 | U19: 15 | V19: 15 | W19: 0.5 | X19: * | Y19: 4 | AA19: 15 | AB19: 15 | AC19: 0.5 | AG19: =SUM(B19:AF19) -> 161.5 | AH19: =SUM(AG19-AG61) -> -4
A20: Q. RSW | C20: 1 | D20: 1 | I20: 1 | J20: 1 | O20: 1 | P20: 1 | U20: 1 | V20: 1 | AA20: 1 | AB20: 1 | AG20: =SUM(B20:AF20) -> 10
A21: Sarah | B21: DS | C21: DS | H21: DS | I21: DS | N21: DS | O21: DS | T21: DS | U21: DS | Z21: DS | AA21: DS | AF21: DS | AG21: =SUM(B21:AF21) -> 0
A22: Newson | B22: 15 | C22: 15 | D22: 0.5 | H22: 15 | I22: 15 | J22: 0.5 | K22: 4 | N22: 15 | O22: 15 | P22: 0.5 | T22: 15 | U22: 15 | V22: 0.5 | Y22: 4 | Z22: 15 | AA22: 15 | AB22: 0.5 | AF22: 15 | AG22: =SUM(B22:AF22) -> 175.5 | AH22: =SUM(AG22-AG61) -> 10
A23: Q. RSW | B23: 1 | C23: 1 | H23: 1 | I23: 1 | N23: 1 | O23: 1 | T23: 1 | U23: 1 | Z23: 1 | AA23: 1 | AF23: 1 | AG23: =SUM(B23:AF23) -> 11
AG24: =SUM(B24:AF24) -> 0
AG25: =SUM(B25:AF25) -> 0 | AH25: =SUM(AG25-AG61) -> -165.5
AG26: =SUM(B26:AF26) -> 0
A27: Sam | F27: DS | G27: DS | L27: DS | M27: DS | R27: DS | S27: DS | X27: DS | Y27: DS | AD27: DS | AE27: DS | AG27: =SUM(B27:AF27) -> 0
A28: Lawrence | F28: 15 | G28: 15 | H28: 0.5 | K28: 4 | L28: 15 | M28: 15 | N28: 0.5 | R28: 15 | S28: 15 | T28: 0.5 | X28: 15 | Y28: 15 | Z28: 0.5 | AD28: 15 | AE28: 15 | AF28: 0.5 | AG28: =SUM(B28:AF28) -> 156.5 | AH28: =SUM(AG28-AG61) -> -9
A29: UQ. RSW | F29: 1 | G29: 1 | L29: 1 | M29: 1 | R29: 1 | S29: 1 | X29: 1 | Y29: 1 | AD29: 1 | AE29: 1 | AG29: =SUM(B29:AF29) -> 10
A30: Olivia | D30: DS | E30: DS | J30: DS | K30: DS | P30: DS | Q30: DS | V30: DS | W30: DS | AB30: DS | AC30: DS | AG30: =SUM(B30:AF30) -> 0
A31: Machnik | D31: 15 | E31: 15 | F31: 0.5 | J31: 15 | K31: 15 | L31: 0.5 | P31: 15 | Q31: 15 | R31: 0.5 | V31: 15 | W31: 15 | X31: 0.5 | Y31: 4 | AB31: 15 | AC31: 15 | AD31: 0.5 | AG31: =SUM(B31:AF31) -> 156.5 | AH31: =SUM(AG31-AG61) -> -9
A32: UQ. RSW | D32: 1 | E32: 1 | J32: 1 | K32: 1 | P32: 1 | Q32: 1 | V32: 1 | W32: 1 | AB32: 1 | AC32: 1 | AG32: =SUM(B32:AF32) -> 10
A33: James | AG33: 0
A34: Logan | AG34: =SUM(B34:AF34) -> 0
A35: Bank | AG35: =SUM(B35:AF35) -> 0
AG36: 0
AG37: =SUM(B37:AF37) -> 0
AG38: =SUM(B38:AF38) -> 0
AG39: 0
AG40: =SUM(B40:AF40) -> 0
...

Sheet January
A1: Bodkin Way | B1: 1 | C1: 2 | D1: 3 | E1: 4 | F1: 5 | G1: 6 | H1: 7 | I1: 8 | J1: 9 | K1: 10 | L1: 11 | M1: 12 | N1: 13 | O1: 14 | P1: 15 | Q1: 16 | R1: 17 | S1: 18 | T1: 19 | U1: 20 | V1: 21 | W1: 22 | X1: 23 | Y1: 24 | Z1: 25 | AA1: 26 | AB1: 27 | AC1: 28 | AD1: 29 | AE1: 30 | AF1: 31 | AG1: ASI | AH1: Over/Under
A2: Jan. | B2: F | C2: S | D2: SU | E2: M | F2: T | G2: W | H2: TH | I2: F | J2: S | K2: SU | L2: M | M2: T | N2: W | O2: TH | P2: F | Q2: S | R2: SU | S2: M | T2: T | U2: W | V2: TH | W2: F | X2: S | Y2: SU | Z2: M | AA2: T | AB2: W | AC2: TH | AD2: F | AE2: S | AF2: SU | AG2: =SUM(AG5,AG8,AG11,AG17,AG20,AG23,AG26,AG29,AG32,AG35,AG38,AG41,AG44,AG47,AG50,AG53,AG56,AG59) -> 62 | AH2: Hours
A3: Ellen | B3: A | E3: A | F3: A | G3: A | H3: A | I3: A | L3: A | M3: A | N3: A | O3: A | P3: A | S3: A | T3: A | U3: A | V3: A | W3: A | Z3: A | AA3: A | AB3: A | AC3: A | AD3: A | AG3: =SUM(B3:AF3) -> 0
A4: Middleton | B4: 7.5 | E4: 7.5 | F4: 7.5 | G4: 7.5 | H4: 7.5 | I4: 7.5 | L4: 7.5 | M4: 7.5 | N4: 7.5 | O4: 7.5 | P4: 7.5 | S4: 7.5 | T4: 7.5 | U4: 7.5 | V4: 7.5 | W4: 7.5 | Z4: 7.5 | AA4: 7.5 | AB4: 7.5 | AC4: 7.5 | AD4: 7.5 | AG4: =SUM(B4:AF4) -> 157.5
A5: RM | AG5: =SUM(B5:AF5) -> 0
A6: Charlotte | B6: A | E6: A | F6: A | G6: A | H6: A | I6: A | L6: A | M6: A | N6: A | O6: A | P6: A | S6: A | T6: A | U6: A | V6: A | W6: A | Z6: A | AA6: A | AB6: A | AC6: A | AD6: A | AG6: =SUM(B6:AF6) -> 0
A7: Watson | B7: 7.5 | E7: 7.5 | F7: 7.5 | G7: 7.5 | H7: 7.5 | I7: 7.5 | L7: 7.5 | M7: 7.5 | N7: 7.5 | O7: 7.5 | P7: 7.5 | S7: 7.5 | T7: 7.5 | U7: 7.5 | V7: 7.5 | W7: 7.5 | Z7: 7.5 | AA7: 7.5 | AB7: 7.5 | AC7: 7.5 | AD7: 7.5 | AG7: =SUM(B7:AF7) -> 157.5 | AH7: =SUM(AG7-AG61) -> -8
A8: DM | AG8: =SUM(B8:AF8) -> 0
A9: Philip | F9: DS | G9: DS | L9: DS | M9: DS | R9: DS | S9: DS | X9: DS | Y9: DS | AD9: DS | AE9: DS | AG9: =SUM(B9:AF9) -> 0
A10: Thomas | F10: 15 | G10: 15 | H10: 5.5 | L10: 15 | M10: 15 | N10: 0.5 | R10: 15 | S10: 15 | T10: 0.5 | V10: 5 | X10: 15 | Y10: 15 | Z10: 0.5 | AD10: 15 | AE10: 15 | AF10: 0.5 | AG10: =SUM(B10:AF10) -> 162.5 | AH10: =SUM(AG10-AG61) -> -3
A11: SRSW | F11: 1 | G11: 1 | L11: 1 | M11: 1 | R11: 1 | S11: 1 | X11: 1 | Y11: 1 | AD11: 1 | AE11: 1 | AG11: =SUM(B11:AF11) -> 10
AG12: =SUM(B12:AF12) -> 0
AG13: =SUM(B13:AF13) -> 0 | AH13: =SUM(AG13-AG58) -> 0
AG14: =SUM(B14:AF14) -> 0
A15: Michelle | D15: DS | E15: DS | J15: DS | K15: DS | P15: DS | Q15: DS | V15: DS | W15: DS | AB15: DS | AC15: DS | AG15: =SUM(B15:AF15) -> 0
A16: McSporran | D16: 15 | E16: 15 | F16: 0.5 | H16: 5 | J16: 15 | K16: 15 | L16: 0.5 | P16: 15 | Q16: 15 | R16: 0.5 | V16: 15 | W16: 15 | X16: 0.5 | AB16: 15 | AC16: 15 | AD16: 0.5 | AG16: =SUM(B16:AF16) -> 157.5 | AH16: =SUM(AG16-AG61) -> -8
A17: SRSW | D17: 1 | E17: 1 | J17: 1 | K17: 1 | P17: 1 | Q17: 1 | V17: 1 | W17: 1 | AB17: 1 | AC17: 1 | AG17: =SUM(B17:AF17) -> 10
A18: Jack | B18: DS | C18: DS | H18: DS | I18: DS | N18: DS | O18: DS | T18: DS | U18: DS | Z18: DS | AA18: DS | AF18: DS | AG18: =SUM(B18:AF18) -> 0
A19: McMahon | B19: 15 | C19: 15 | D19: 0.5 | H19: 15 | I19: 15 | J19: 0.5 | N19: 15 | O19: 15 | P19: 0.5 | T19: 15 | U19: 15 | V19: 5.5 | Z19: 15 | AA19: 15 | AB19: 0.5 | AF19: 15 | AG19: =SUM(B19:AF19) -> 172.5 | AH19: =SUM(AG19-AG61) -> 7
A20: Q. RSW | B20: 1 | C20: 1 | H20: 1 | I20: 1 | N20: 1 | O20: 1 | T20: 1 | U20: 1 | Z20: 1 | AA20: 1 | AF20: 1 | AG20: =SUM(B20:AF20) -> 11
A21: Sarah | B21: DS | G21: DS | H21: DS | M21: DS | N21: DS | S21: DS | T21: DS | Y21: DS | Z21: DS | AE21: DS | AF21: DS | AG21: =SUM(B21:AF21) -> 0
A22: Newson | B22: 15 | C22: 0.5 | G22: 15 | H22: 15 | I22: 0.5 | M22: 15 | N22: 15 | O22: 0.5 | S22: 15 | T22: 15 | U22: 0.5 | V22: 4 | Y22: 15 | Z22: 15 | AA22: 0.5 | AE22: 15 | AF22: 15 | AG22: =SUM(B22:AF22) -> 171.5 | AH22: =SUM(AG22-AG61) -> 6
A23: Q. RSW | B23: 1 | G23: 1 | H23: 1 | M23: 1 | N23: 1 | S23: 1 | T23: 1 | Y23: 1 | Z23: 1 | AE23: 1 | AF23: 1 | AG23: =SUM(B23:AF23) -> 11
AG24: =SUM(B24:AF24) -> 0
AG25: =SUM(B25:AF25) -> 0 | AH25: =SUM(AG25-AG61) -> -165.5
AG26: =SUM(B26:AF26) -> 0
A27: Sam | E27: DS | F27: DS | K27: DS | L27: DS | P27: DS | Q27: DS | W27: DS | X27: DS | AC27: DS | AD27: DS | AG27: =SUM(B27:AF27) -> 0
A28: Lawrence | E28: 15 | F28: 15 | G28: 0.5 | H28: 4 | K28: 15 | L28: 15 | M28: 0.5 | P28: 15 | Q28: 15 | R28: 0.5 | V28: 4 | W28: 15 | X28: 15 | Y28: 0.5 | AC28: 15 | AD28: 15 | AE28: 0.5 | AG28: =SUM(B28:AF28) -> 160.5 | AH28: =SUM(AG28-AG61) -> -5
A29: UQ. RSW | E29: 1 | F29: 1 | K29: 1 | L29: 1 | P29: 1 | Q29: 1 | W29: 1 | X29: 1 | AC29: 1 | AD29: 1 | AG29: =SUM(B29:AF29) -> 10
A30: Olivia | C30: DS | D30: DS | I30: DS | J30: DS | O30: DS | P30: DS | U30: DS | V30: DS | AA30: DS | AB30: DS | AG30: =SUM(B30:AF30) -> 0
A31: Machnik | C31: 15 | D31: 15 | E31: 0.5 | H31: 4 | I31: 15 | J31: 15 | K31: 0.5 | O31: 15 | P31: 15 | Q31: 0.5 | U31: 15 | V31: 15 | W31: 0.5 | AA31: 15 | AB31: 15 | AC31: 0.5 | AG31: =SUM(B31:AF31) -> 156.5 | AH31: =SUM(AG31-AG61) -> -9
A32: UQ. RSW | C32: 1 | D32: 1 | I32: 1 | J32: 1 | O32: 1 | P32: 1 | U32: 1 | V32: 1 | AA32: 1 | AB32: 1 | AG32: =SUM(B32:AF32) -> 10
A33: James | AG33: 0
A34: Logan | AG34: =SUM(B34:AF34) -> 0
A35: Bank | AG35: =SUM(B35:AF35) -> 0
AG36: 0
AG37: =SUM(B37:AF37) -> 0
AG38: =SUM(B38:AF38) -> 0
AG39: 0
AG40: =SUM(B40:AF40) -> 0
...

Sheet February
A1: Bodkin Way | B1: 1 | C1: 2 | D1: 3 | E1: 4 | F1: 5 | G1: 6 | H1: 7 | I1: 8 | J1: 9 | K1: 10 | L1: 11 | M1: 12 | N1: 13 | O1: 14 | P1: 15 | Q1: 16 | R1: 17 | S1: 18 | T1: 19 | U1: 20 | V1: 21 | W1: 22 | X1: 23 | Y1: 24 | Z1: 25 | AA1: 26 | AB1: 27 | AC1: 28 | AD1: ASI | AE1: Over/Under
A2: February | B2: M | C2: T | D2: W | E2: TH | F2: F | G2: S | H2: SU | I2: M | J2: T | K2: W | L2: TH | M2: F | N2: S | O2: SU | P2: M | Q2: T | R2: W | S2: TH | T2: F | U2: S | V2: SU | W2: M | X2: T | Y2: W | Z2: TH | AA2: F | AB2: S | AC2: SU | AD2: =SUM(AD5,AD8,AD11,AD17,AD20,AD23,AD26,AD29,AD32,AD35,AD38,AD41,AD44,AD47,AD50,AD53,AD56,AD59) -> 54 | AE2: Hours
A3: Ellen | B3: A | C3: A | D3: A | E3: A | F3: A | I3: A | J3: A | K3: A | L3: A | M3: A | P3: A | Q3: A | R3: A | S3: A | T3: A | W3: A | X3: A | Y3: A | Z3: A | AA3: A | AD3: =SUM(B3:AC3) -> 0
A4: Middleton | B4: 7.5 | C4: 7.5 | D4: 7.5 | E4: 7.5 | F4: 7.5 | I4: 7.5 | J4: 7.5 | K4: 7.5 | L4: 7.5 | M4: 7.5 | P4: 7.5 | Q4: 7.5 | R4: 7.5 | S4: 7.5 | T4: 7.5 | W4: 7.5 | X4: 7.5 | Y4: 7.5 | Z4: 7.5 | AA4: 7.5 | AD4: =SUM(B4:AC4) -> 150
A5: RM | AD5: =SUM(B5:AC5) -> 0
A6: Charlotte | B6: A | C6: A | D6: A | E6: A | F6: A | I6: A | J6: A | K6: A | L6: A | M6: A | P6: A | Q6: A | R6: A | S6: A | T6: A | W6: A | X6: A | Y6: A | Z6: A | AA6: A | AD6: =SUM(B6:AC6) -> 0
A7: Watson | B7: 7.5 | C7: 7.5 | D7: 7.5 | E7: 7.5 | F7: 7.5 | I7: 7.5 | J7: 7.5 | K7: 7.5 | L7: 7.5 | M7: 7.5 | P7: 7.5 | Q7: 7.5 | R7: 7.5 | S7: 7.5 | T7: 7.5 | W7: 7.5 | X7: 7.5 | Y7: 7.5 | Z7: 7.5 | AA7: 7.5 | AD7: =SUM(B7:AC7) -> 150 | AE7: =SUM(AD7-AD61) -> 0
A8: DM | AD8: =SUM(B8:AC8) -> 0
A9: Philip | E9: DS | F9: DS | K9: DS | L9: DS | Q9: DS | R9: DS | W9: DS | X9: DS | AC9: DS | AD9: =SUM(B9:AC9) -> 0
A10: Thomas | E10: 15 | F10: 15 | G10: 0.5 | K10: 15 | L10: 15 | M10: 0.5 | Q10: 15 | R10: 15 | S10: 0.5 | W10: 15 | X10: 15 | Y10: 0.5 | Z10: 5 | AC10: 15 | AD10: =SUM(B10:AC10) -> 142 | AE10: =SUM(AD10-AD61) -> -8
A11: SRSW | E11: 1 | F11: 1 | K11: 1 | L11: 1 | Q11: 1 | R11: 1 | W11: 1 | X11: 1 | AC11: 1 | AD11: =SUM(B11:AC11) -> 9
AD12: =SUM(B12:AC12) -> 0
AD13: =SUM(B13:AC13) -> 0 | AE13: =SUM(AD13-AD58) -> 0
AD14: =SUM(B14:AC14) -> 0
A15: Michelle | C15: DS | D15: DS | I15: DS | J15: DS | O15: DS | P15: DS | U15: DS | V15: DS | AA15: DS | AB15: DS | AD15: =SUM(B15:AC15) -> 0
A16: McSporran | C16: 15 | D16: 15 | E16: 0.5 | I16: 15 | J16: 15 | K16: 0.5 | L16: 5 | O16: 15 | P16: 15 | Q16: 0.5 | U16: 15 | V16: 15 | W16: 0.5 | Z16: 5 | AA16: 15 | AB16: 15 | AC16: 0.5 | AD16: =SUM(B16:AC16) -> 162.5 | AE16: =SUM(AD16-AD61) -> 12.5
A17: SRSW | C17: 1 | D17: 1 | I17: 1 | J17: 1 | O17: 1 | P17: 1 | U17: 1 | V17: 1 | AA17: 1 | AB17: 1 | AD17: =SUM(B17:AC17) -> 10
A18: Jack | B18: DS | G18: DS | H18: DS | M18: DS | N18: DS | S18: 2 | T18: 2 | Y18: DS | Z18: DS | AD18: =SUM(B18:AC18) -> 4
A19: McMahon | B19: 15 | C19: 0.5 | G19: 15 | H19: 15 | I19: 0.5 | L19: 5 | M19: 15 | N19: 15 | O19: 0.5 | S19: 15 | T19: 15 | Y19: 15 | Z19: 15 | AA19: 0.5 | AD19: =SUM(B19:AC19) -> 142 | AE19: =SUM(AD19-AD61) -> -8
A20: Q. RSW | B20: 1 | G20: 1 | H20: 1 | M20: 1 | N20: 1 | Y20: 1 | Z20: 1 | AD20: =SUM(B20:AC20) -> 7
A21: Sarah | F21: DS | G21: DS | L21: DS | M21: DS | R21: DS | S21: DS | X21: DS | Y21: DS | AD21: =SUM(B21:AC21) -> 0
A22: Newson | F22: 15 | G22: 15 | H22: 0.5 | L22: 15 | M22: 15 | N22: 0.5 | R22: 15 | S22: 15 | T22: 0.5 | X22: 15 | Y22: 15 | Z22: 0.5 | AD22: =SUM(B22:AC22) -> 122 | AE22: =SUM(AD22-AD61) -> -28
A23: Q. RSW | F23: 1 | G23: 1 | L23: 1 | M23: 1 | R23: 1 | S23: 1 | X23: 1 | Y23: 1 | AD23: =SUM(B23:AC23) -> 8
AD24: =SUM(B24:AC24) -> 0
AD25: =SUM(B25:AC25) -> 0 | AE25: =SUM(AD25-AD61) -> -150
AD26: =SUM(B26:AC26) -> 0
A27: Sam | D27: DS | E27: DS | J27: DS | K27: DS | P27: DS | Q27: DS | V27: DS | W27: DS | AB27: DS | AC27: DS | AD27: =SUM(B27:AC27) -> 0
A28: Lawrence | D28: 15 | E28: 15 | F28: 0.5 | J28: 15 | K28: 15 | L28: 4.5 | P28: 15 | Q28: 15 | R28: 0.5 | V28: 15 | W28: 15 | X28: 0.5 | Z28: 5 | AB28: 15 | AC28: 15 | AD28: =SUM(B28:AC28) -> 161 | AE28: =SUM(AD28-AD61) -> 11
A29: UQ. RSW | D29: 1 | E29: 1 | J29: 1 | K29: 1 | P29: 1 | Q29: 1 | V29: 1 | W29: 1 | AB29: 1 | AC29: 1 | AD29: =SUM(B29:AC29) -> 10
A30: Olivia | B30: DS | C30: DS | H30: DS | I30: DS | N30: DS | O30: DS | T30: DS | U30: DS | Z30: DS | AA30: DS | AD30: =SUM(B30:AC30) -> 0
A31: Machnik | B31: 15 | C31: 15 | D31: 0.5 | H31: 15 | I31: 15 | J31: 0.5 | L31: 4 | N31: 15 | O31: 15 | P31: 0.5 | T31: 15 | U31: 15 | V31: 0.5 | Z31: 15 | AA31: 15 | AB31: 0.5 | AD31: =SUM(B31:AC31) -> 156.5 | AE31: =SUM(AD31-AD61) -> 6.5
A32: UQ. RSW | B32: 1 | C32: 1 | H32: 1 | I32: 1 | N32: 1 | O32: 1 | T32: 1 | U32: 1 | Z32: 1 | AA32: 1 | AD32: =SUM(B32:AC32) -> 10
A33: James | AD33: =SUM(B33:AC33) -> 0
A34: Logan | AD34: =SUM(B34:AC34) -> 0
A35: Bank | AD35: =SUM(B35:AC35) -> 0
AD36: =SUM(B36:AC36) -> 0
AD37: =SUM(B37:AC37) -> 0
AD38: =SUM(B38:AC38) -> 0
AD39: =SUM(B39:AC39) -> 0
AD40: =SUM(B40:AC40) -> 0
...

Sheet March
A1: Bodkin Way | B1: 1 | C1: 2 | D1: 3 | E1: 4 | F1: 5 | G1: 6 | H1: 7 | I1: 8 | J1: 9 | K1: 10 | L1: 11 | M1: 12 | N1: 13 | O1: 14 | P1: 15 | Q1: 16 | R1: 17 | S1: 18 | T1: 19 | U1: 20 | V1: 21 | W1: 22 | X1: 23 | Y1: 24 | Z1: 25 | AA1: 26 | AB1: 27 | AC1: 28 | AD1: 29 | AE1: 30 | AF1: 31 | AG1: ASI | AH1: Over/Under
A2: March | B2: M | C2: T | D2: W | E2: TH | F2: F | G2: S | H2: SU | I2: M | J2: T | K2: W | L2: TH | M2: F | N2: S | O2: SU | P2: M | Q2: T | R2: W | S2: TH | T2: F | U2: S | V2: SU | W2: M | X2: T | Y2: W | Z2: TH | AA2: F | AB2: S | AC2: SU | AD2: M | AE2: T | AF2: W | AG2: =SUM(AG5,AG8,AG11,AG17,AG20,AG23,AG26,AG29,AG32,AG35,AG38,AG41,AG44,AG47,AG50,AG53,AG56,AG59) -> 62 | AH2: Hours
A3: Ellen | B3: A | C3: A | D3: A | E3: A | F3: A | I3: A | J3: A | K3: A | L3: A | M3: A | P3: A | Q3: A | R3: A | S3: A | T3: A | W3: A | X3: A | Y3: A | Z3: A | AA3: A | AD3: A | AE3: A | AF3: A | AG3: =SUM(B3:AF3) -> 0
A4: Middleton | B4: 7.5 | C4: 7.5 | D4: 7.5 | E4: 7.5 | F4: 7.5 | I4: 7.5 | J4: 7.5 | K4: 7.5 | L4: 7.5 | M4: 7.5 | P4: 7.5 | Q4: 7.5 | R4: 7.5 | S4: 7.5 | T4: 7.5 | W4: 7.5 | X4: 7.5 | Y4: 7.5 | Z4: 7.5 | AA4: 7.5 | AD4: 7.5 | AE4: 7.5 | AF4: 7.5 | AG4: =SUM(B4:AF4) -> 172.5
A5: RM | AG5: =SUM(B5:AF5) -> 0
A6: Charlotte | B6: A | C6: A | D6: A | E6: A | F6: A | I6: A | J6: A | K6: A | L6: A | M6: A | P6: A | Q6: A | R6: A | S6: A | T6: A | W6: A | X6: A | Y6: A | Z6: A | AA6: A | AD6: A | AE6: A | AF6: A | AG6: =SUM(B6:AF6) -> 0
A7: Watson | B7: 7.5 | C7: 7.5 | D7: 7.5 | E7: 7.5 | F7: 7.5 | I7: 7.5 | J7: 7.5 | K7: 7.5 | L7: 7.5 | M7: 7.5 | P7: 7.5 | Q7: 7.5 | R7: 7.5 | S7: 7.5 | T7: 7.5 | W7: 7.5 | X7: 7.5 | Y7: 7.5 | Z7: 7.5 | AA7: 7.5 | AD7: 7.5 | AE7: 7.5 | AF7: 7.5 | AG7: =SUM(B7:AF7) -> 172.5 | AH7: =SUM(AG7-AG61) -> 7
A8: DM | AG8: =SUM(B8:AF8) -> 0
A9: Philip | B9: DS | G9: DS | H9: DS | M9: DS | N9: DS | S9: DS | T9: DS | Y9: DS | Z9: DS | AE9: DS | AF9: DS | AG9: =SUM(B9:AF9) -> 0
A10: Thomas | B10: 15 | C10: 0.5 | G10: 15 | H10: 15 | I10: 0.5 | L10: 5 | M10: 15 | N10: 15 | O10: 0.5 | S10: 15 | T10: 15 | U10: 0.5 | Y10: 15 | Z10: 15 | AA10: 0.5 | AE10: 15 | AF10: 15 | AG10: =SUM(B10:AF10) -> 172.5 | AH10: =SUM(AG10-AG61) -> 7
A11: SRSW | B11: 1 | G11: 1 | H11: 1 | M11: 1 | N11: 1 | S11: 1 | T11: 1 | Y11: 1 | Z11: 1 | AE11: 1 | AF11: 1 | AG11: =SUM(B11:AF11) -> 11
AG12: =SUM(B12:AF12) -> 0
AG13: =SUM(B13:AF13) -> 0 | AH13: =SUM(AG13-AG58) -> 0
AG14: =SUM(B14:AF14) -> 0
A15: Michelle | E15: DS | F15: DS | K15: DS | L15: DS | Q15: DS | R15: DS | W15: DS | X15: DS | AC15: DS | AD15: DS | AG15: =SUM(B15:AF15) -> 0
